Workbook

Sheet gen-abstract
A2: NAME OF WORK :- CONSTRUCTION OF COMMERCIAL COMPLEX FOR PANCHAYAT SAMITI GIRWA, UDAIPUR
A5: GENERAL ABSTRACT OF COST
B7: PART 'A' CIVIL WORK BASEMENT, GROUND FLOOR AND FIRST FLOOR | F7: Rs. | G7: =GF1_ABS!G263 -> #REF!
B9: PART 'B' SANITARY & WATER SUPPLY WORK | F9: Rs. | G9: ='sanitary-abs'!G47 -> 81418
B11: PART 'C' ELECTRIC WORK @ 12% OF Civil Work | F11: Rs. | G11: =G7*0.12 -> #REF!
F13: TOTAL Rs. | G13: =SUM(G7:G11) -> #REF!
B15: Add @ 5 % for Electric Fixtures On Civil Work Part 'A'
C16: i.e. on Rs. | D16: =G7 -> #REF! | F16: Rs. | G16: =ROUNDUP(D16*0.05,0) -> #REF!
E17: GRAND TOTAL Rs. | G17: =SUM(G13:G16) -> #REF!
F19: SAY Rs. | G19: =ROUNDUP(G17/1000000,2)*10 -> #REF!
G20: Lacs.
E22: CHARTERED ENGINEER,
E23: TEJHANS INVESTMENTS, UDAIPUR

Sheet GF1_ABS
A1: ='gen-abstract'!A2 -> NAME OF WORK :- CONSTRUCTION OF COMMERCIAL COMPLEX FOR PANCHAYAT SAMITI GIRWA, UDAIPUR
A2: PART 'A' CIVIL WORK BASEMENT, GROUND FLOOR AND FIRST FLOOR
A3: ABSTRACT OF COST
A4: S.No. | B4: Particulars. | C4: Quantity | E4: Rate | F4: Unit | G4: Amount
A5: 1 | B5: Earth work in excavation in foundation trenches or drains including dressing of sides and ramming of bottoms, lift up to 1.5 Mtr. including taking out the excavated soil and depositing and refilling of jhiri with watering & ramming and disposal of surplus excavated soil as directed within a lead of 50 meter. All kinds of soil. | C5: =GF1_MES!K51 -> 1548.5904 | D5: Cum | E5: 92 | F5: P Cum | G5: =C5*E5 -> 142470.32
A6: 2 | B6: Filling available excavated earth (excluding rock) in trenches, plinth side of foundation etc. in layers not exceeding 20 cm. in depth , consolidating each deposited layer by ramming and watering including lead upto 50Mtr. and lift upto 1.5Mtr. | C6: =GF1_MES!K80 -> 1168.582 | D6: Cum | E6: 44 | F6: P Cum | G6: =C6*E6 -> 51417.608
A7: 3 | B7: Providing and injection Chloropyrifous Emulsifiable concentrate 20 % with 1 % concentration for PRE-CONSGTRUCTIONAL Anti termite treatment as per IS 6313 part III and amended from time to time and creating a continous chemical barrier under and around the column pits, wall trenches, basement excavation, top surface of plinth filling, junction of wall and floor along the external perimeter of building expansion joints, over the top surface of consolidated earth of which aproch is to be laid surrounding of pipes and conduits etc. complete as per specification (Plinth floor area only shall be measured for payment.) | C7: =GF1_MES!K84 -> 1290.492 | D7: Sqm | E7: 180 | G7: =C7*E7 -> 232288.56
A8: 4 | B8: Providing and laying in position cement concrete including curing compaction etc. of specified grade excluding the cost of centering and shuttering =All up to plinth leve 1:4:8 (1Cement :4 Coarse Sand :8 Graded stone aggregate 40 mm nominal size | C8: =GF1_MES!K107 -> 211.8603 | D8: Cum | E8: 2346 | F8: P Cum | G8: =C8*E8 -> 497024.26
A9: 5 | B9: Providing and laying in position specified grade of reinforcement cement concrete all RCC structural elements upto plinth level including curing compaction finishing with rendering in cement sand mortar 1:3 ( 1 cement : 3 coarse sand) and making good the joints excluding the cost of centering shuttering and reinforcementlevel. M25 grade Design mix | C9: =GF1_MES!K219 -> 467.7162 | D9: Cum | E9: 4912 | F9: P Cum | G9: =C9*E9 -> 2297422
A10: 6 | B10: Providing and layin in position specified grade of cement concrete for RCC Structure elements unto floor three level including curing, compaction, finishing with rendering in cement sand mortar 1:3 (1 cement ; 3 coarse sand) and making good the joints excluding the cost of centering shuttering and reinforcement forshuttering and reinforcement : M25 grade Design mix | C10: =GF1_MES!K230 -> 188.1031 | D10: Cum | E10: 5240 | F10: P Cum | G10: =C10*E10 -> 985660.27
A11: 7 | B11: Providing and layin in position specified grade of cement concrete for RCC Structure elements unto floor three level including curing, compaction, finishing with rendering in cement sand mortar 1:3 (1 cement ; 3 coarse sand) and making good the joints excluding the cost of centering shuttering and reinforcement forshuttering and reinforcement : Walls (any thickness) including attached pilasters, buttresses, plinth and string courses, fillets, columns, pillars, piers, abutments, posts and struts etc. M20 grade Nominal Mix | C11: 97 | D11: cum | E11: 4319 | F11: P Cum | G11: =C11*E11 -> 418943
A12: 9 | B12: beams suspended floors roofs griders having slopes up to 15 digree C, landings balconies shelves chajjas lintels bands plain window sills staircases and spiral staircases M20 grade nominal mix | C12: 1993 | D12: Cum | E12: 4300 | F12: P Cum | G12: =C12*E12 -> 8569900
A13: 8 | B13: Centering and shuttering with plywood or steel sheets including strutting, propping, bracing both ways and removal of formwork for foundations in basements rafts, footings, strap beams, bases of columns , etc. up to plinth level. | C13: 3598 | D13: Sqm | E13: 85 | G13: =C13*E13 -> 305830
A14: 9 | B14: Centering & shuttering with ply wood or steel sheets including shuttering , propping, barcing both waves with widen members and removal of form work up to floor three level for:
B15: (A) Suspended floors, roofs, landings, staircases, balconies, girders, cantilevers, bands , coping, bed plates, anchor blocks, sills, chhajjas lintel, beam etc. | C15: 13607 | D15: Sqm | E15: 164 | G15: =C15*E15 -> 2231548
B16: (B) Columns, pillars, posts and struts etc. | C16: 2574 | D16: Sqm | E16: 156 | G16: =C16*E16 -> 401544
A17: 12 | B17: Providing and fabricating reinforcement for R.C.C. work including straightening, cutting, bending, placing in position and binding (including cost of binding wire) all complete up to floor three level. Tremo Mechanically treated bars | C17: =GF1_MES!K247 -> 84030.26 | D17: Kg | E17: 56 | G17: =C17*E17 -> 4705694.5
A18: 13 | B18: Provinding hoisting and fixing up to floor three level precast reinforced concrte work in nominal M20 grade mix including cost of required centering, shuttering finishing smooth with 6 mm thick cement plastr 1:3 ( 1 cement : 3 fine sand) on exposed surface complete excluding cost of reinforcement.Lintels, beams and bressumers including setting in cement mortar 1:3 (1 cement : 3 course sand) aggregate 20mm nominal size. | C18: 5 | D18: cum | E18: 3618 | F18: P Cum | G18: =C18*E18 -> 18090
A19: 14 | B19: Providing and fixing precast R.C.C. slab in M15 nominal mix per design unto 30mm thick for shelves etc, including cost of reinforcement consisting of wire of mesh 100x100mmx4mm with fine finish. | C19: 35 | D19: Sqm | E19: 284 | G19: =C19*E19 -> 9940
A20: 15 | B20: Brick masonry in foundation and plinth with bricks of class designation 75 in : Cement mortar 1 : 6 (1 cement : 6 coarse sand) | C20: 1105 | D20: Cum | E20: 2530 | F20: P Cum | G20: =C20*E20 -> 2795650
A21: 16 | B21: Add extra over item No.5.1 for brick work in super structure upto third storey. | C21: 1105 | D21: Cum | E21: 140 | F21: P Cum | G21: =C21*E21 -> 154700
A22: 17 | B22: Half brick masonry in foundation & plinth using bricks of designation 75 in Cement mortar 1 : 4 (1 cement : 4 coarse sand) | C22: 4067 | D22: Sqm | E22: 293 | G22: =C22*E22 -> 1191631
A23: 18 | B23: Add extra over item no 5.8 for half brick masonry in superstructure up to third storey.including cost of hoop reinforcement (2 nos 6 mm dia MS bars at every fourth course | C23: 4067 | D23: Sqm | E23: 48 | G23: =C23*E23 -> 195216
A24: 19 | B24: Random Rubble stone masonry for foundation and plinth in Cement Sand mortar above 30CM thick wall in: Cement Mortar 1:6 ( 1-Cement : 6-Sand). | C24: 499 | D24: Cum | E24: 1526 | F24: P Cum | G24: =C24*E24 -> 761474
A25: 20 | B25: Supplying and fixing dressed sand or other approved stone shelves, tands in cement mortar 1:3 with fine dressed edges : | G25: =C25*E25 -> 0
A26: 20.1 | B26: 35mm thick. | C26: 45 | D26: Sqm | E26: 385 | G26: =C26*E26 -> 17325
A27: 20.2 | B27: 50mm thick. | C27: 45 | D27: Sqm | E27: 575 | G27: =C27*E27 -> 25875
A28: 21 | B28: Supplying and fixing in walls machine cut and polished stone shelves, tands and sills in CM 1:3 with machine cut edges : Kota Stone 25 to 30 mm thick. | C28: 185 | D28: Sqm | E28: 467 | G28: =C28*E28 -> 86395
A29: 22 | B29: Marble stone flooring table rubbed, 18 mm thick over 20mm (Av.) thick base of CM 1:4 (1 cement : 4 coarse sand) jointing with white cement mortar 1:2 (1 white cement : 2 marble dust) with pigment to match the shade of the marble slab including grinding, rubbing and polishing complete. | G29: =C29*E29 -> 0
A30: 22.1 | B30: Rajnagar 1st quality with light spots. 1501 Cm2 to 3600 Cm2 Tiles | C30: 3414 | D30: Sqm | E30: 1000 | G30: =C30*E30 -> 3414000
A31: 22.2 | B31: Kesriaji (Rikhabdeo).1501 cm2 to 3600 cm2 tiles | C31: 355 | D31: Sqm | E31: 1221 | G31: =C31*E31 -> 433455
A32: 23 | B32: Add extra for doing mirror polishing. | C32: 3464 | D32: Sqm | E32: 92.6 | G32: =C32*E32 -> 320766.4
A33: 24 | B33: Providing and fixing Granite stone slab mirror polished and machine edge cut in walls, pillars, steps, Shelves, Sills Counters, Floors etc. laid on 12mm (Av.) thick base of cement mortar 1:3 (1 cement : 3 coarse sand) jointing with white cement mortar 1:2 (1 white cement : 2 marble dust) with pigment to match the shade of the granite slab complete including rubbing and polishing of : Green / Black / Other granite 1501 Cm2 to 3600 Cm2 Tiles. | C33: 113 | D33: Sqm | E33: 2477 | G33: =C33*E33 -> 279901
A34: 25 | B34: Providing and fixing Ist quality standard White Ivory Glazed Tiles ISI marked [IS:13753] of size 300mm x 200mm in walls, floors, steps, pillars etc. laid on a bed of neat cement slurry finished with flush pointing in white cement mixed with pigment to match the shade of tile complete (excluding the cost of cement plaster). Category-I : Kajariya, Jhonson, Somani make etc. | C34: 5622 | D34: Sqm | E34: 990 | G34: =C34*E34 -> 5565780
A35: 26 | B35: Providing and fixing Ist quality MAT finished ceremic tile size 300x300mm confirming to IS : 13753 colour such as white, grey, ivory, fume red brown in walls, floors, steps, pillars etc. laid on a bed of neat cement slsurry including nicely finished joints using water proof joint filler power (Untile or Roffe make) and finishing with flush pointing in white cement mixed with pigment to match the shade of tile complete (excluding the cost of cement plaster). Category A: Kajaria, Jhonson,Somani make etc. | C35: 543 | D35: sqm | E35: 865 | G35: =C35*E35 -> 469695
A36: 27 | B36: Extra for providing edge moulding (Full) to 18 mm thick marble stone counters, vantities etc. over item No. 7.1 & 7.2 including machine polishing to edge to give high gloss finish etc. complete as per design approved by Engineer-in-Charge. | G36: =C36*E36 -> 0
A37: 27.1 | B37: Marble work | C37: 390 | D37: Mtr | E37: 122 | G37: =C37*E37 -> 47580
A38: 27.2 | B38: Granite work. | C38: 72 | D38: Mtr | E38: 200 | G38: =C38*E38 -> 14400
A39: 28 | B39: P & F Vitrified Porcelain Polished tiles on floor, skirting and steps etc. in different sizes (thickness to be specified by manufacture) with water absortion less than 0.08% and conforming to IS 15622 of approved make in all colour and shade, laid with 20 mm thick CM 1:4 including grouting the joints with white cement and matching pigment etc complete (Oreva, Nitco and equivalent as approved by Engineer-incharge) Size 600 mm x 600 mm | C39: 2566 | D39: Sqm | E39: 1208 | G39: =C39*E39 -> 3099728
A40: 29 | B40: Other Fitting. Providing and Fixing hydraulic door closure ISI marked. | C40: 59 | D40: Each | E40: 674 | G40: =C40*E40 -> 39766
...

Sheet GF1_MES
A1: ='gen-abstract'!A2 -> NAME OF WORK :- CONSTRUCTION OF COMMERCIAL COMPLEX FOR PANCHAYAT SAMITI GIRWA, UDAIPUR
A3: PART 'A' CIVIL WORK FIRST FLOOR
A4: DETAILS OF MEASUREMENTS
A5: S.N. | B5: Particulars | C5: Nos. | E5: Length | G5: Breadth | I5: Height | K5: Qty. | L5: Units
B6: Center to center distances
B7: Ground Floor
B8: Main walls 230 mm th. in x and Y Direction
B9: Back Side | C9: 1 | D9: x | E9: 3.58 | J9: = | K9: =IF(C9,C9*E9,"") -> 3.58 | L9: RM
C10: 1 | D10: x | E10: 6.4 | J10: = | K10: =IF(C10,C10*E10,"") -> 6.4 | L10: RM
C11: 1 | D11: x | E11: 3.2 | J11: = | K11: =IF(C11,C11*E11,"") -> 3.2 | L11: RM
C12: 1 | D12: x | E12: 3.2 | J12: = | K12: =IF(C12,C12*E12,"") -> 3.2 | L12: RM
C13: 1 | D13: x | E13: 5.33 | J13: = | K13: =IF(C13,C13*E13,"") -> 5.33 | L13: RM
B14: Left Side | C14: 1 | D14: x | E14: 7.62 | J14: = | K14: =IF(C14,C14*E14,"") -> 7.62 | L14: RM
C15: 1 | D15: x | E15: 4.27 | J15: = | K15: =IF(C15,C15*E15,"") -> 4.27 | L15: RM
C16: 1 | D16: x | E16: 7.62 | J16: = | K16: =IF(C16,C16*E16,"") -> 7.62 | L16: RM
B17: Front Side | C17: 1 | D17: x | E17: 3.58 | J17: = | K17: =IF(C17,C17*E17,"") -> 3.58 | L17: RM
C18: 1 | D18: x | E18: 3.2 | J18: = | K18: =IF(C18,C18*E18,"") -> 3.2 | L18: RM
B19: Right Side | C19: 1 | D19: x | E19: 25.6 | J19: = | K19: =IF(C19,C19*E19,"") -> 25.6 | L19: RM
B20: Staircase | C20: 2 | D20: x | E20: 3.35 | J20: = | K20: =IF(C20,C20*E20,"") -> 6.7 | L20: RM
B21: Lobby/ Shop | C21: 1 | D21: x | E21: 5.49 | J21: = | K21: =IF(C21,C21*E21,"") -> 5.49 | L21: RM
I22: TOTAL | J22: = | K22: =SUM(K9:K21) -> 85.79 | L22: RM
B24: PARAPET WALL 230 MM
B25: Back Side | C25: 1 | D25: x | E25: 3.58 | J25: = | K25: =IF(C25,C25*E25,"") -> 3.58 | L25: RM
C26: 1 | D26: x | E26: 6.4 | J26: = | K26: =IF(C26,C26*E26,"") -> 6.4 | L26: RM
C27: 1 | D27: x | E27: 3.2 | J27: = | K27: =IF(C27,C27*E27,"") -> 3.2 | L27: RM
C28: 1 | D28: x | E28: 3.2 | J28: = | K28: =IF(C28,C28*E28,"") -> 3.2 | L28: RM
C29: 1 | D29: x | E29: 5.33 | J29: = | K29: =IF(C29,C29*E29,"") -> 5.33 | L29: RM
B30: Left Side | C30: 1 | D30: x | E30: 7.62 | J30: = | K30: =IF(C30,C30*E30,"") -> 7.62 | L30: RM
C31: 1 | D31: x | E31: 4.27 | J31: = | K31: =IF(C31,C31*E31,"") -> 4.27 | L31: RM
C32: 1 | D32: x | E32: 7.62 | J32: = | K32: =IF(C32,C32*E32,"") -> 7.62 | L32: RM
B33: Front Side | C33: 1 | D33: x | E33: 3.58 | J33: = | K33: =IF(C33,C33*E33,"") -> 3.58 | L33: RM
C34: 1 | D34: x | E34: 3.2 | J34: = | K34: =IF(C34,C34*E34,"") -> 3.2 | L34: RM
B35: Right Side | C35: 1 | D35: x | E35: 25.6 | J35: = | K35: =IF(C35,C35*E35,"") -> 25.6 | L35: RM
I36: TOTAL | J36: = | K36: =SUM(K25:K35) -> 73.6 | L36: RM
B37: Brick Partition walls in X and Y Direction
B38: Shops 2,3 | C38: 3 | D38: x | E38: 7.39 | J38: = | K38: =IF(C38,C38*E38,"") -> 22.17 | L38: RM
B39: Shops 6,7 in Y Direction | C39: 2 | D39: x | E39: 5.49 | J39: = | K39: =IF(C39,C39*E39,"") -> 10.98 | L39: RM
B40: Shops 6,1 in X Direction | C40: 2 | D40: x | E40: 3.35 | J40: = | K40: =IF(C40,C40*E40,"") -> 6.7 | L40: RM
B41: Shop 7 in X Direction | C41: 1 | D41: x | E41: 3.05 | J41: = | K41: =IF(C41,C41*E41,"") -> 3.05 | L41: RM
B42: Shop 4 in X Direction | C42: 1 | D42: x | E42: 5.26 | J42: = | K42: =IF(C42,C42*E42,"") -> 5.26 | L42: RM
...

Sheet sanitary-abs
A1: ='gen-abstract'!A2 -> NAME OF WORK :- CONSTRUCTION OF COMMERCIAL COMPLEX FOR PANCHAYAT SAMITI GIRWA, UDAIPUR
A2: PART 'B' SANITARY & WATER SUPPLY WORK
A3: ABSTRACT OF COST
A4: S.No. | B4: Particulars. | C4: Quantity | E4: Rate | F4: Unit | G4: Amount
A5: 1 | B5: P & F Indian Type white glazed vitreous china Ist quality WC Orissa Pan (IS : 2556 Mark) with 100 mm vitreous china P or S trap including cutting and making good the wall and floor. Size 580x440 mm | C5: 3 | D5: Nos. | E5: 890 | F5: Each | G5: =IF(C5,ROUNDUP(C5*E5,0),"") -> 2670
A6: =A5+1 -> 2 | B6: P & F Flush cock/Flush valve (IS : 9758 Mark) for WC of approved quality make : C.P. Brass concealed 25 mm | C6: 3 | D6: Nos. | E6: 650 | F6: Each | G6: =IF(C6,ROUNDUP(C6*E6,0),"") -> 1950
A7: =IF(A6,A6+1,#REF!+1) -> 3 | B7: P & F WVC wash basin (Ist quality, IS : 2556 Mark) of approved make with C.I. brackets duly painted 1 No. 15 mm C.P. Pillar cock (IS : 8934 Mark) & 32 mm C.P. Brass waste coupling of approved make, 25 mm G.I. waste pipe complete including cutting and making good the wall size 580mmx450mm. | C7: =sanitary_MEASUR!K12 -> 3 | D7: Nos. | E7: 1250 | F7: Each | G7: =IF(C7,ROUNDUP(C7*E7,0),"") -> 3750
A8: =IF(A7,A7+1,A6+1) -> 4 | B8: P&F beveled edge mirror of special glass of approved make (Atul or equivalent) complete with 6 mm thick Asbestos Cement sheet ground fixed to wooden screws & washers sizes 600 x 450 mm x 4 mm thick. | C8: =sanitary_MEASUR!K13 -> 3 | D8: Nos. | E8: 210 | F8: Each | G8: =IF(C8,ROUNDUP(C8*E8,0),"") -> 630
A9: =IF(A8,A8+1,A7+1) -> 5 | B9: P & F grating of approved/quality make : Cast iron. | C9: =sanitary_MEASUR!K17 -> 6 | D9: Nos. | E9: 30 | F9: Each | G9: =IF(C9,ROUNDUP(C9*E9,0),"") -> 180
A10: =IF(A9,A9+1,A8+1) -> 6 | B10: P & F GI Pipes (Internal work) with G.I. fittings (IS : 1239 Mark) & MS clamps, including cutting and making good the wall and floors : | G10: =IF(C10,ROUNDUP(C10*E10,0),"")
A11: A. | B11: 15 mm Dai nominal bore `B’ Class. | C11: =sanitary_MEASUR!K22 -> 27 | D11: RM | E11: 70 | F11: P RM | G11: =IF(C11,ROUNDUP(C11*E11,0),"") -> 1890
A12: B. | B12: 25 mm Dai nominal bore `B’ Class | C12: =sanitary_MEASUR!K27 -> 90.6 | D12: RM | E12: 117 | F12: P RM | G12: =IF(C12,ROUNDUP(C12*E12,0),"") -> 10601
A13: 7 | B13: P & F GI Pipes (External work) with G.I. fittings (IS : 1239 Mark) , including trenching and refilling earth etc. : | G13: =IF(C13,ROUNDUP(C13*E13,0),"")
A14: A. | B14: 25 mm Dai nominal bore `B’ Class. | C14: =sanitary_MEASUR!K32 -> 120 | D14: RM | E14: 98 | F14: P RM | G14: =IF(C14,ROUNDUP(C14*E14,0),"") -> 11760
A15: =A13+1 -> 8 | B15: Making connection of G.I. distribution branch with G.I. main including all fittings . (a) upto 25 mm Dai. | C15: =sanitary_MEASUR!K35 -> 9 | D15: Nos. | E15: 100 | F15: Each | G15: =IF(C15,ROUNDUP(C15*E15,0),"") -> 900
A16: 9 | B16: P & F Bib Cock (IS : 8931 Mark) superior quality of approved make : Brass 400 gram 15 mm | C16: =sanitary_MEASUR!K39 -> 4 | D16: Nos. | E16: 120 | F16: Each | G16: =IF(C16,ROUNDUP(C16*E16,0),"") -> 480
A17: =IF(A16,A16+1,#REF!+1) -> 10 | B17: P & F Stop Cock (IS : 8931 Mark) superior quality of approved make : Brass 400 gram 15 mm | C17: =sanitary_MEASUR!K42 -> 3 | D17: Nos. | E17: 120 | F17: Each | G17: =IF(C17,ROUNDUP(C17*E17,0),"") -> 360
A18: 11 | B18: P/F full way valve (IS:778 Mark) or wheel valve of approved make: gun metal | G18: =IF(C18,ROUNDUP(C18*E18,0),"")
B19: (A) 15 mm | C19: =sanitary_MEASUR!K46 -> 3 | D19: Nos. | E19: 150 | F19: Each | G19: =IF(C19,ROUNDUP(C19*E19,0),"") -> 450
B20: (B) 25 mm | C20: =sanitary_MEASUR!K49 -> 2 | D20: Nos. | E20: 300 | F20: Each | G20: =IF(C20,ROUNDUP(C20*E20,0),"") -> 600
A21: =IF(A18,A18+1,#REF!+1) -> 12 | B21: P & F PVC Storage Tank confirming to IS standards of approved make with cover, 25 mm Dai 1 M long C.I. over flow pipe & 25 cm. long wash out pipe with plug and socket, including making connection, etc. complete of approved design: | G21: =IF(C21,ROUNDUP(C21*E21,0),"")
B22: (A) 1000 (liters capacity). | C22: 4 | D22: Nos. | E22: =5000 -> 5000 | F22: Each | G22: =IF(C22,ROUNDUP(C22*E22,0),"") -> 20000
B23: (B) 500 (liters capacity). | C23: =sanitary_MEASUR!K52 -> 1 | D23: Nos. | E23: =2500 -> 2500 | F23: Each | G23: =IF(C23,ROUNDUP(C23*E23,0),"") -> 2500
A24: =IF(A21,A21+1,A18+1) -> 13 | B24: P & F Ball Cock (IS : 1703 Mark) with Rod & PVC Ball complete : | G24: =IF(C24,ROUNDUP(C24*E24,0),"")
B25: (A) Brass wt. 400 gram 15 mm. | C25: 5 | D25: Nos. | E25: 150 | F25: Each | G25: =IF(C25,ROUNDUP(C25*E25,0),"") -> 750
A26: =IF(A24,A24+1,A21+1) -> 14 | B26: Providing and fixing Unplasticized Poly Vinyl Chloride (UPVC) SWR pipes type B for soil and rain and waste discharge system (IS:13592 : 1992 marked) of approved quality/ make including jointing the pipes complete. | G26: =IF(C26,ROUNDUP(C26*E26,0),"")
B27: (A) 110 mm dia. | C27: =sanitary_MEASUR!K60 -> 11 | D27: RM | E27: =200 -> 200 | F27: P RM | G27: =IF(C27,ROUNDUP(C27*E27,0),"") -> 2200
A28: 15 | B28: Providing and fixing Unplasticized Poly Vinyl Chloride (UPVC) SWR pipe fittings type B for soil and rain and waste discharge system (IS:13592 : 1992 marked) of approved quality/ make including jointing the pipes complete. | G28: =IF(C28,ROUNDUP(C28*E28,0),"")
A29: A. | B29: 110 mm dia. Offset | C29: 1 | D29: Nos. | E29: 162 | F29: Each | G29: =IF(C29,ROUNDUP(C29*E29,0),"") -> 162
A30: B. | B30: 110 mm dia. Coupler | C30: 5 | D30: Nos. | E30: 62 | F30: Each | G30: =IF(C30,ROUNDUP(C30*E30,0),"") -> 310
A31: C. | B31: 110 mm dia. Single 'Y' with Door | C31: 1 | D31: Nos. | E31: 199 | F31: Each | G31: =IF(C31,ROUNDUP(C31*E31,0),"") -> 199
A32: D. | B32: 100 mm dia. vent Cowl | C32: =sanitary_MEASUR!K65 -> 3 | D32: Nos. | E32: 34 | F32: Each | G32: =IF(C32,ROUNDUP(C32*E32,0),"") -> 102
A33: E. | B33: 110 mm dia. Single 'Y' | C33: 1 | D33: Nos. | E33: 159 | F33: Each | G33: =IF(C33,ROUNDUP(C33*E33,0),"") -> 159
A34: F. | B34: 110 mm dia. door Bend | C34: 1 | D34: Nos. | E34: 111 | F34: Each | G34: =IF(C34,ROUNDUP(C34*E34,0),"") -> 111
A35: G. | B35: 110 mm dia. Bend 87.5 degree. | C35: 1 | D35: Nos. | E35: 89 | F35: Each | G35: =IF(C35,ROUNDUP(C35*E35,0),"") -> 89
A36: 16 | B36: Providing and fixing Spun Cast Iron (SCI ) Floor Trap (Nahni) of (IS : 3789mark) approved quality /make with socket down or hinged grating including cutting and making good the floor :- size 100x100 mm. | C36: =sanitary_MEASUR!K69 -> 2 | D36: Nos. | E36: 140 | F36: Each | G36: =IF(C36,ROUNDUP(C36*E36,0),"") -> 280
A37: 17 | B37: Construction of manhole in all types of soil inner size 90 x 60 Cm with 300 mm thick masonry in CM 1:6, 10 cm. thick cement concrete 1:5:10 in foundation, 20 mm thick inside plaster in CM 1:6, finished with floating neat cement, 50 mm thick M-15 grade CC flooring, making channels, 80 mm thick stone slab covering with 40 mm thick M-15 grade C.C. flooring, 25 Kg CI cover with frame of 450 mm Dai. earth work etc. Complete as per approved drawing including disposal of surplus earth within a lead of 50 m. | G37: =IF(C37,ROUNDUP(C37*E37,0),"")
B38: (A) Depth upto 0.5 M | C38: =sanitary_MEASUR!K71 -> 2 | D38: Nos. | E38: 1500 | F38: Each | G38: =IF(C38,ROUNDUP(C38*E38,0),"") -> 3000
B39: (B) Depth 0.5 M to 1.0 M | C39: =sanitary_MEASUR!K72 -> 1 | D39: Nos. | E39: 2050 | F39: Each | G39: =IF(C39,ROUNDUP(C39*E39,0),"") -> 2050
A40: =IF(A37,A37+1,#REF!+1) -> 18 | B40: Supplying and fixing C.I. cover with frame, C.I. gratings for chambers & man holes. | C40: =sanitary_MEASUR!K73 -> 75 | D40: Kg. | E40: 12 | F40: P Kg. | G40: =IF(C40,ROUNDUP(C40*E40,0),"") -> 900
...

Sheet sanitary_MEASUR
A1: ='gen-abstract'!A2 -> NAME OF WORK :- CONSTRUCTION OF COMMERCIAL COMPLEX FOR PANCHAYAT SAMITI GIRWA, UDAIPUR
A2: PART 'B' SANITARY & WATER SUPPLY WORK
A3: DETAILS OF MEASUREMENTS
A4: S.N. | B4: Particulars | C4: Nos. | E4: Length | G4: Breadth | I4: Height | K4: Qty. | L4: Units
A5: 1 | B5: P & F Indian Type white glazed vitreous china Ist quality WC Orissa Pan (IS : 2556 Mark) with 100 mm vitreous china P or S trap including cutting and making good the wall and floor. Size 580x440 mm
C6: 3 | D6: x | E6: 1 | J6: =IF(K6,"=","") -> = | K6: =C6*E6 -> 3 | L6: Nos.
A7: =A5+1 -> 2 | B7: P & F Flush cock/Flush valve (IS : 9758 Mark) for WC of approved quality make : C.P. Brass concealed 25 mm | J7: =IF(K7,"=","")
C8: 3 | D8: x | E8: 1 | J8: =IF(K8,"=","") -> = | K8: =C8*E8 -> 3 | L8: Nos.
H9: Total | J9: =IF(K9,"=","") -> = | K9: =SUM(K8:K8) -> 3 | L9: Nos.
A10: =IF(A7,A7+1,A5+1) -> 3 | J10: =IF(K10,"=","")
C11: 3 | D11: x | E11: 1 | J11: =IF(K11,"=","") -> = | K11: =C11*E11 -> 3 | L11: Nos.
H12: Total | J12: =IF(K12,"=","") -> = | K12: =SUM(K11:K11) -> 3 | L12: Nos.
A13: =IF(A10,A10+1,A7+1) -> 4 | B13: P&F bevelled edge mirror of special glass of approved make (Atul or equivalent) complete with 6 mm thick Asbestos Cement sheet ground fixed to wooden screws & washers sizes 600 x 450 mm x 4 mm thick. | C13: =K12 -> 3 | D13: x | E13: 1 | J13: =IF(K13,"=","") -> = | K13: =C13*E13 -> 3 | L13: Nos.
A15: 5 | B15: P & F grating of approved/quality make : Cast iron. | J15: =IF(K15,"=","")
B16: G.F. | C16: 6 | D16: x | E16: 1 | J16: =IF(K16,"=","") -> = | K16: =C16*E16 -> 6 | L16: Nos.
H17: Total | J17: =IF(K17,"=","") -> = | K17: =SUM(K16:K16) -> 6 | L17: Nos.
A18: 6 | B18: P & F GI Pipes (Internal work) with G.I. fittings (IS : 1239 Mark) & MS clamps, including cutting and making good the walls and floors : | J18: =IF(K18,"=","")
A19: A. | B19: 15 mm dia nominal bore `B’ Class. | J19: =IF(K19,"=","")
B20: W.C. Internal plumbing | C20: 3 | D20: x | E20: 4.5 | J20: =IF(K20,"=","") -> = | K20: =C20*E20 -> 13.5 | L20: RM
B21: W.B. Internal plumbing | C21: 3 | D21: x | E21: 4.5 | J21: =IF(K21,"=","") -> = | K21: =C21*E21 -> 13.5 | L21: RM
H22: Total | J22: =IF(K22,"=","") -> = | K22: =SUM(K19:K21) -> 27 | L22: RM
A23: B. | B23: 25 mm dia nominal bore `B’ Class | J23: =IF(K23,"=","")
B24: Uptake pipes | C24: 2 | D24: x | E24: 16.2 | J24: =IF(K24,"=","") -> = | K24: =C24*E24 -> 32.4 | L24: RM
B25: Down take | C25: 3 | D25: x | E25: 14 | J25: =IF(K25,"=","") -> = | K25: =C25*E25 -> 42 | L25: RM
B26: Down take for W.C. | C26: 2 | D26: x | E26: 8.1 | J26: =IF(K26,"=","") -> = | K26: =C26*E26 -> 16.2 | L26: RM
H27: Total | J27: =IF(K27,"=","") -> = | K27: =SUM(K23:K26) -> 90.6 | L27: RM
A28: =A18+1 -> 7 | B28: P & F GI Pipes (External work) with G.I. fittings (IS : 1239 Mark) , including trenching and refilling earth etc. : | J28: =IF(K28,"=","")
A29: A. | B29: 25 mm dia nominal bore `B’ Class. | J29: =IF(K29,"=","")
B30: Ring main | C30: 2 | D30: x | E30: 30 | J30: =IF(K30,"=","") -> = | K30: =C30*E30 -> 60 | L30: RM
B31: Court yard | C31: 4 | D31: x | E31: 15 | J31: =IF(K31,"=","") -> = | K31: =C31*E31 -> 60 | L31: RM
H32: Total | J32: =IF(K32,"=","") -> = | K32: =SUM(K30:K31) -> 120 | L32: RM
A33: =A28+1 -> 8 | B33: Making connection of G.I. distribution branch with G.I. main including all fittings . (a) upto 25 mm dia. | J33: =IF(K33,"=","")
B34: Toilets | C34: 3 | D34: x | E34: 3 | J34: =IF(K34,"=","") -> = | K34: =C34*E34 -> 9 | L34: Nos.
H35: Total | J35: =IF(K35,"=","") -> = | K35: =SUM(K34:K34) -> 9 | L35: Nos.
A36: =A33+1 -> 9 | B36: P & F Bib Cock (IS : 8931 Mark) superior quality of approved make : Brass 400 gram 15 mm | J36: =IF(K36,"=","")
B37: W.C. | C37: 3 | D37: x | E37: 1 | J37: =IF(K37,"=","") -> = | K37: =C37*E37 -> 3 | L37: Nos.
B38: Court Yard | C38: 1 | D38: x | E38: 1 | J38: =IF(K38,"=","") -> = | K38: =C38*E38 -> 1 | L38: Nos.
H39: Total | J39: =IF(K39,"=","") -> = | K39: =SUM(K37:K38) -> 4 | L39: Nos.
A40: =IF(A36,A36+1,#REF!+1) -> 10 | B40: P & F Stop Cock (IS : 8931 Mark) superior quality of approved make : Brass 400 gram 15 mm | J40: =IF(K40,"=","")
B41: W.B. | C41: 3 | D41: x | E41: 1 | J41: =IF(K41,"=","") -> = | K41: =C41*E41 -> 3 | L41: Nos.
...

Sheet tech report
A1: ='gen-abstract'!A2 -> NAME OF WORK :- CONSTRUCTION OF COMMERCIAL COMPLEX FOR PANCHAYAT SAMITI GIRWA, UDAIPUR
A3: Technical Report
A5: 1. Name of Work | C5: : | D5: Construction of Police Station at AMET
A7: 2. Administrative Sanction | C7: :
A9: 3.Location | C9: : | D9: The proposed Hostels shall be constructed at AMET, Rajsamand
A11: 4. Specifications | C11: : | D11: The general specifications adopted for the work are in accordance with the P.W.D. detailed specifications. Brief specifications are narrated below:-
B13: I Foundation concrete | C13: : | D13: Cement concrete 1:5:10 , 150 mm thick.
B15: II Masonry for Foundation | C15: : | D15: Random rubble stone masonry in cement sand mortar 1:6
B17: III Damp proof coarse | C17: : | D17: 75 mm thick P.C.C. M-15.
B19: IV Super structure masonry | C19: : | D19: Stone masonry in cement sand mortar 1:6 walls.
B21: V Lintels | C21: : | D21: R.C.C. M-15 with M.S. reinforcement.
B23: VI Partition | C23: : | D23: Bricks class 75 in cement sand mortar 1:4 (115 mm thick)
B25: VII Base of Flooring | C25: : | D25: 100 mm thick in 1:5 :10 mix
B27: VIII Flooring | D27: 40 mm thick marble chips flooring.
B29: (c) White Glazed Tiles | C29: : | D29: Hostel Building
D30: In Urinals 1200 mm high Dado, in WC's 900 mm High Dado.
B32: IX Plaster | C32: : | D32: 20 mm thick in cement mortar 1:6 over stone masonry and 20 mm thick in cement mortar 1:6 over brick masonry.
B34: X Joinery frames | C34: : | D34: Door frames of mild steel selection (EZ-7 Section)
B36: XI Door Shutters | C36: : | D36: 35 mm thick fully panelled doors with Assam Teak wood frame with 12 mm thick Shuttering Ply Panels for doors 1005 to 1200 mm wide and for other doors 30 mm thick fully panelled doors with Assam Teak wood frame with 9 mm thick Shuttering Ply Panels.
B38: XII Finishing | C38: : | D38: Colour washing at outside, white washing at inside all rooms and ceilings; enamel paints on wood and steel work.
B40: Sanitary work | C40: : | D40: As per P.W.D. specification.
A42: 5. Scope of work | C42: :
B44: Police Station Building | D44: Plinth Area GF 328 Sqm, FF 10.50 Sqm. Total 339.50 Sqm
D45: Ground Floor with Barrack, Wireless Room, Record Room, SHO Room, IO Room, Malkhana, Office & Male Female lockups, store, staircase 2 toilet blocks. In First floor only head room.
A47: 6. Basis of Estimate | C47: : | D47: Estimate prepared on the basis of PWD B.S.R. -1998.
A49: 7. Estimated Cost | C49: : | D49: Estimated cost of work comes to Rs. 20.00 Lacs. It includes the Prorata charges @ 13%.
A51: 8. Drawings | C51: : | D51: Plan, elevation & section are enclosed.
A54: ASSISTANT ENGINEER, | D54: EXECUTIVE ENGINEER,
A55: P.W.D. Sub Div.- AMET | D55: P.W.D. Div.- AMET

Sheet joinery shedule
A1: Particulars | B1: Size in MM | D1: In 380 mm Wall | E1: In Partition Wall
A2: Steel Shutter | B2: 1200x2100 | C2: D1 | D2: 3
A3: Double Leaf Shutter | B3: 1200x2100 | C3: D2 | D3: 2 | F3: 35
A4: Double Leaf Shutter | B4: 900x2100 | C4: D3 | D4: 2 | F4: 35
A5: Single Leaf Shutter | B5: 1050x2100 | C5: D4 | D5: 3 | F5: 35
A6: Single Leaf Shutter | B6: 900x2100 | C6: D5 | D6: 4 | F6: 35
A7: Single Leaf Shutter | B7: 750x2100 | C7: D6 | D7: 0 | E7: 4 | F7: 30
A9: Windows | B9: 1800x1700 | C9: W1 | D9: 6
A10: Windows | B10: 1200x1700 | C10: W2 | D10: 4
A11: Windows | B11: 900x1700 | C11: W3 | D11: 10
A12: Vents | B12: 1200x600 | C12: V1 | D12: 1
A13: Vents | B13: 900x600 | C13: V2 | D13: 1
A14: Vents | B14: 600x600 | C14: V3 | D14: 5

Sheet Sheet11
A1: 1 | B1: x | C1: 11.75 | D1: =ROUND(C1*0.3048,2) -> 3.58
C2: 21 | G2: 115 | H2: =ROUND(G2*0.3048,2) -> 35.05
C3: 21 | G3: 153.5 | H3: =ROUND(G3*0.3048,2) -> 46.79 | I3: =H2+H3 -> 81.84 | J3: =I3/2 -> 40.92
C4: 17.5 | G4: 159 | H4: =ROUND(G4*0.3048,2) -> 48.46
C5: =SUM(C1:C4) -> 71.25 | D5: =ROUND(C5*0.3048,2) -> 21.72 | G5: 51.5 | H5: =ROUND(G5*0.3048,2) -> 15.7
C6: 21 | D6: =ROUND(C6*0.3048,2) -> 6.4 | E6: =
C7: 69 | D7: =ROUND(C7*0.3048,2) -> 21.03
E8: =SUM(D5:D6) -> 28.12
G14: =1.8^2 -> 3.24
G15: =1.05^2 -> 1.1025
G16: =SUM(G14:G15) -> 4.3425 | H16: =G16^0.5 -> 2.0838666

Sheet Sheet12

Sheet Sheet13

Sheet Sheet14

Sheet Sheet15

Sheet Sheet16
