Workbook

Sheet Metadata
A1: Project Information
A3: Project Name | B3: Modified DJ Quarter - Programmatic Demo
A4: Location | B4: Udaipur, Rajasthan
A5: Client Name | B5: Public Works Department
A6: Engineer Name | B6: Er. Demo Engineer
A7: Date Prepared | B7: 2025-11-08
A8: Estimated Cost | B8: 0
A9: Notes | B9: This estimate was created programmatically using the EstimateCloner. Modifications include updated measurements and new BSR items.
A10: Created From | B10: DJ QUARTER.xlsx
A11: Created Date | B11: 2025-11-08T21:16:52.714980
A12: Modifications | B12: 0
A15: Modifications Log

Sheet tech report
A1: ='gen-abstract'!A2
A3: Technical Report
A5: 1. Name of Work | C5: : | D5: Construction of Judicial Courts Building at Nathdwara
A7: 2. Administrative Sanction | C7: :
A9: 3.Location | C9: : | D9: The proposed Judicial Courts shall be constructed at NATHDWARA, Rajsamand
A11: 4. Specifications | C11: : | D11: The general specifications adopted for the work are in accordance with the P.W.D. detailed specifications. Brief specifications are narrated below:-
B12: Judicial Courts Building & Bar Wing & PP Wing Building
B13: I Foundation concrete | C13: : | D13: Cement concrete 1:4:8 , 300 mm thick.
B15: II Masonry for Foundation | C15: : | D15: Random rubble stone masonry in cement sand mortar 1:6
B17: III Damp proof coarse | C17: : | D17: 100 mm thick R.C.C. M-20.
B19: IV Super structure masonry | C19: : | D19: Stone masonry in cement sand mortar 1:6 walls.
B21: V Lintels | C21: : | D21: R.C.C. M-20 with steel reinforcement.
B23: VI Partition | C23: : | D23: Bricks class 75 in cement sand mortar 1:4 (115 mm thick)
B25: VII Base of Flooring | C25: : | D25: 100 mm thick in 1:5 :10 mix over 230 mm thick dry stone kharanja.
B27: VIII Flooring | C27: (I) Judicial Courts Building
D28: Kota Stone Flooring :- 25 mm thick blue Kota stone flooring laid over 20 thick base of 1 : 4 CSM in all rooms and Corridor except entrance hall..
D29: Marble Slab Flooring :- In Entrance Hall 18 to 20 mm thick Rajnagar grade I Marble slab flooring laid over 20 thick base of 1 : 4 CSM.
D30: White Glazed Tiles:- In all toilets and sanitary units I class white glazed tiles dado shall be provided.
C31: (II) Bar Wing & PP Wing
D32: Kota Stone Flooring :- 25 mm thick blue Kota stone flooring laid over 20 thick base of 1 : 4 CSM in all rooms and Corridor except entrance hall..
D33: White Glazed Tiles:- In all toilets and sanitary units I class white glazed tiles dado shall be provided.
B35: IX Plaster | C35: : | D35: 20 mm thick in cement mortar 1:6 over stone masonry and 20 mm thick in cement mortar 1:6 over brick masonry. Araish plaster shall be applied on inside walls and ceilings.
B37: X Joinery frames | C37: : | D37: Door frames of mild steel selection built with T- Section (Angle 50 x 50 x 6 mm and flat 50 x 6 mm)
B39: XI Door Shutters | C39: : | D39: 35 mm thick fully panelled doors with Assam Teak wood frame with 12 mm thick Shuttering Ply Panels for doors 1005 to 1200 mm wide and for other doors 30 mm thick fully panelled doors with Assam Teak wood frame with 9 mm thick Shuttering Ply Panels.
B41: XII Finishing | C41: : | D41: Finishing with water cement paint at outside, Oil Bound distemper at inside all rooms and ceilings; enamel paints on wood and steel work.
B43: Sanitary work | C43: : | D43: As per P.W.D. specification.
B45: Compound Wall
B46: I Foundation concrete | C46: : | D46: Cement concrete 1:4:8 , 150 mm thick.
B48: II Masonry for Foundation | C48: : | D48: Random rubble stone masonry in cement sand mortar 1:8
B50: III Super structure masonry | C50: : | D50: Stone masonry in cement sand mortar 1:8 walls.
B53: IV Plaster | C53: : | D53: 20 mm thick in cement mortar 1:6 over stone masonry and 20 mm thick in cement mortar 1:6 over brick masonry. Araish plaster shall be applied on inside walls and ceilings.
B55: V Finishing | C55: : | D55: Finishing with water cement paint at outside, enamel paints on steel work gates and cow catcher.
B56: Parking Shed
B57: I Foundation concrete | C57: : | D57: Cement concrete 1:4:8 , 150 mm thick.
B59: II Masonry for Foundation | C59: : | D59: Random rubble stone masonry in cement sand mortar 1:6
B61: III Roofing | C61: : | D61: R.C.C. M-20 with steel reinforcement.
B63: IV Base of Flooring | C63: : | D63: 100 mm thick in 1:5 :10 mix over 230 mm thick dry stone kharanja.
B65: V Flooring | D65: 20 mm thick Chequered Tiles flooring laid over 20 mm thick cement sand mortar mix 1 : 6.
A66: 5. Scope of work | C66: :
B67: (I) Judicial Courts Building | D67: Plinth Area GF 2244.20 Sqm, FF 16.70 Sqm. Total 2260.90 Sqm
...

Sheet gen-abstract
A2: NAME OF WORK :- Construction of Additional Session Judge Bungalow at Nathdwara
A5: GENERAL ABSTRACT OF COST
B7: PART 'A' CIVIL WORK GROUND FLOOR | F7: Rs. | G7: =GF1_ABS!G55
B9: PART 'B' SANITARY & WATER SUPPLY WORK | F9: Rs. | G9: ='sanitary-abs'!G51
F11: TOTAL Rs. | G11: =SUM(G7:G9)
B13: Add @ 7 % for Electrification On Civil Work Part 'A'
C14: i.e. on Rs. | D14: =G7 | F14: Rs. | G14: =ROUNDUP(D14*0.07,0)
F15: TOTAL Rs. | G15: =SUM(G11:G14)
B17: Add Prorata Charges @ 13% | G17: =ROUNDUP(G15*0.13,0)
E18: GRAND TOTAL Rs. | G18: =SUM(G15:G17)
B23: ASSISTANT ENGINEER, | F23: EXECUTIVE ENGINEER,
B24: P.W.D. Sub Div.- NATHDWARA | F24: P.W.D. Div.- RAJSAMAND

Sheet GF1_ABS
A1: ='gen-abstract'!A2
A2: PART 'A' CIVIL WORK GROUND FLOOR
A3: ABSTRACT OF COST
A4: S.No. | B4: Particulars. | C4: Quantity | E4: Rate | F4: Unit | G4: Amount
A5: 1 | B5: Earth work in excavation in foundation trenches or drains including dressing of sides and ramming of bottoms, lift upto 1.5 Mtr. including taking out the excavated soil and depositing and refilling of Jhiri with watering and ramming and disposal of surplus excavated soil as directed within a lead of 50 m. 'Hard soil mixed with boulders | C5: =GF1_MES!K67 | D5: Cum | E5: 37.1 | F5: P Cum | G5: =IF(C5,ROUNDUP(C5*E5,0),"")
A6: =A5+1 | B6: Earth work in excavation in foundation trenches or drains including dressing of sides and ramming of bottoms, lift upto 1.5 Mtr. including taking out the excavated soil and depositing and refilling of Jhiri with watering and ramming and disposal of surplus excavated soil as directed within a lead of 50 m. including stacking material available.
B7: (a) Decomposed Rock | C7: =GF1_MES!K70 | D7: Cum | E7: 44.5 | F7: P Cum | G7: =IF(C7,ROUNDUP(C7*E7,0),"")
B8: (b) Ordinary Rock | C8: =GF1_MES!K72 | D8: Cum | E8: 58 | F8: P Cum | G8: =IF(C8,ROUNDUP(C8*E8,0),"")
B9: (c) Phylite Rock | C9: =GF1_MES!K74 | D9: Cum | E9: 85 | F9: P Cum | G9: =IF(C9,ROUNDUP(C9*E9,0),"")
A10: 3 | B10: Filling in plinth available excavated earth (excluding rock) in trenches, plinth side of foundation, etc. in layers not exceeding 20 cm. in depth, consolidating each deposited layer by ramming and watering including lead upto 50 Mtr and lift upto 1.5 Mtr. | C10: =GF1_MES!K90 | D10: Cum. | E10: 9 | F10: P Cum. | G10: =IF(C10,ROUNDUP(C10*E10,0),"")
A11: =A10+1 | B11: Earth work in excavation over areas (Exceeding 30 cm in depth, 1.5 m in width as well as 10 Sqm on plan) including disposal of excavated earth , lead upto 50 m and lift upto 1.5 Mtr., disposed soil to be neatly dressed; Hard soil mixed with boulders. | C11: =GF1_MES!K95 | D11: Cum. | E11: 29.7 | F11: P Cum. | G11: =IF(C11,ROUNDUP(C11*E11,0),"")
A12: =A11+1 | B12: Carriage of earth including loading, unloading complete with lead 0.50 KM. | C12: =GF1_MES!K98 | D12: Cum. | E12: 30.5 | F12: P Cum. | G12: =IF(C12,ROUNDUP(C12*E12,0),"")
A13: 6 | B13: Providing and laying Cement concrete including curing compaction etc. complete using stone aggregate 40 mm nominal size in foundation plinth, excluding the cost of shuttering, using : 1 Cement : 4 Sand : 8 aggregate Mix. | C13: =GF1_MES!K102 | D13: Cum | E13: 910 | F13: P Cum | G13: =IF(C13,ROUNDUP(C13*E13,0),"")
A14: =A13+1 | B14: R.R. Stone masonry for foundation and plinth in cement sand mortar 1:6 for above 30 cms thick walls. | C14: =GF1_MES!K118 | D14: Cum | E14: =550+140 | F14: P Cum | G14: =IF(C14,ROUNDUP(C14*E14,0),"")
A15: =A14+1 | B15: R.R. Stone masonry for super structure upto 4.5 m height above plinth level in cement sand mortar 1:6 for walls upto 30 cms in thickness. | C15: =GF1_MES!K146 | D15: Cum | E15: 785 | F15: P Cum | G15: =IF(C15,ROUNDUP(C15*E15,0),"")
A16: 9 | B16: Add extra for pillar masonry including bed plates as per specification (Bed plates to be paid separately) in cement sand mortar 1:4 | C16: =GF1_MES!K149 | D16: Cum | E16: 285 | F16: P Cum | G16: =IF(C16,ROUNDUP(C16*E16,0),"")
A17: =A16+1 | B17: Half brick masonry in super structure using bricks of class designation 75 in Cement Mortar 1:4 ( 1 cement : 4 coarse sand) | C17: =GF1_MES!K167 | D17: Sqm | E17: =140+4 | F17: P Sqm | G17: =IF(C17,ROUNDUP(C17*E17,0),"")
A18: =A17+1 | B18: Brick work in superstructure upto 4.5 metre height above plinth level Cement Mortar 1:4 with bricks are class designation 75. | C18: =GF1_MES!K172 | D18: Cum | E18: =1100+32 | F18: P Cum | G18: =IF(C18,ROUNDUP(C18*E18,0),"")
A19: 12 | B19: Centering & shuttering with plywood or steel sheets including strutting propping, bracing both ways with wooden members and removal of form work
B20: (A) For foundation in basements, rafts, footings, strap beams, bases of columns etc. upto plinth level | C20: =GF1_MES!K178 | D20: Sqm | E20: 53 | F20: P Sqm | G20: =IF(C20,ROUNDUP(C20*E20,0),"")
B21: (B) For suspended floors, roofs, landing staircases, landing balconies, girders, cantilevers, bands, copings, bed plates, anchor blocks, sills, chajjas etc. for superstructure upto 4.5 Mtr. height above plinth level | C21: =GF1_MES!K250 | D21: Sqm | E21: 70 | F21: P Sqm | G21: =IF(C21,ROUNDUP(C21*E21,0),"")
A22: =A19+1 | B22: Providing and laying cement concrete and RCC work including curing, compaction, finishing with rendering in cement sand mortar 1:3 (1 cement , 3 : coarse sand) and making good the joints excluding cost of centering and shuttering and reinforcement. 'M-20 grade mix 1:1.5:3(1:cement, :1.5- coarse Sand: 3- graded stone aggregate 20 mm nominal size). (A) In suspended floors, roofs, girders, cantilevers, staircases, landings, balconies, bands, copings, bed plates, anchor blocks, sill, and beams etc. upto 4.5 m height above plinth level. | C22: =GF1_MES!K297 | D22: Cum | E22: =1860+21 | F22: P Cum | G22: =IF(C22,ROUNDUP(C22*E22,0),"")
B23: (B) In Lintels, chajjas, Shelves, vertical and horizontal individually or forming box louvers, bands and facias and fins etc.. upto 4.5 m height above plinth level | C23: =GF1_MES!K314 | D23: Cum | E23: =1860+60 | F23: P Cum | G23: =IF(C23,ROUNDUP(C23*E23,0),"")
B24: (C) In foundations rafts , footings, strap beams, bases of columns | C24: =GF1_MES!K319 | D24: Cum | E24: 1860 | F24: P Cum | G24: =IF(C24,ROUNDUP(C24*E24,0),"")
A25: =A22+1 | B25: Providing and fabrication steel reinforcement for R.C.C. work including cutting, bending, placing in position and binding complete including cost of binding wire in foundations, Raft footing step Beams base of column etc. upto plinth level. Hot rolled deformed (IS : 1139) cold twisted (IS : 1786) bars. | C25: =GF1_MES!K324 | D25: Kg | E25: 18.65 | F25: P Kg | G25: =IF(C25,ROUNDUP(C25*E25,0),"")
A26: 15 | B26: Plaster on new surface on walls in cement sand mortar 1:6 including raking of joints etc. complete fine finished : 20 mm thick. | C26: =GF1_MES!K386 | D26: Sqm | E26: 37 | F26: P Sqm | G26: =IF(C26,ROUNDUP(C26*E26,0),"")
A27: 16 | B27: Plaster on new surface over ceiling in cement sand mortar 1:3 including raking of joints etc. complete fine finished :12 mm thick. | C27: =GF1_MES!K390 | D27: Sqm | E27: 55 | F27: P Sqm | G27: =IF(C27,ROUNDUP(C27*E27,0),"")
A28: 17 | B28: Random rubble dry stone kharanja under floor. | C28: =GF1_MES!K392 | D28: Cum | E28: 180 | F28: P Cum | G28: =IF(C28,ROUNDUP(C28*E28,0),"")
A29: =A28+1 | B29: =GF1_MES!B394 | C29: =GF1_MES!K401 | D29: Kg | E29: 26 | F29: P Kg | G29: =IF(C29,ROUNDUP(C29*E29,0),"")
A30: 19 | B30: Providing and fixing steel glazed doors windows and ventilator shutters of standard rolled steel section joints mitered and welded with steel lugs 13x3 mm, 10 cm long embedded in cement concrete block 15x10x10 cm. of 1:3:6 (1 cement : 3 coarse sand : 6 graded stone aggregate 20 mm nominal size) or with wooden plugs and screws or with fixing clips and screws or with bolt and nuts as required including providing & fixing of plain glass panes 3 mm thick with glazing clips and special metals sash putty of approved make or metal beading with screws complete including priming coat of approved steel primer excluding cost of metal beading and other fixing except necessary hinges of pivots steel handles peg stay etc. as required. Partly Fixed and Partly Openable (Fixed area not to exceed 33%). | C30: =GF1_MES!K409 | D30: Sqm | E30: 700 | F30: P Sqm | G30: =IF(C30,ROUNDUP(C30*E30,0),"")
A31: =A30+1 | B31: Providing and fixing square bars or other flat welded to window, ventilators etc. | C31: =GF1_MES!K418 | D31: Kg | E31: 19 | F31: P Kg | G31: =IF(C31,ROUNDUP(C31*E31,0),"")
A32: =A31+1 | B32: Supplying and fixing wire gauge of 14 mesh x 24 gauge to the metal frame of rolled section by metal beading 20 x 3 mm with suitable screw at not exceeding 150 mm distance. | C32: =GF1_MES!K420 | D32: Sqm | E32: 185 | F32: P Sqm | G32: =IF(C32,ROUNDUP(C32*E32,0),"")
A33: =A32+1 | B33: Supplying and fixing in cement mortar welded hand railing made out of MS round or square bars flats. etc. for staircase or verandah as per design complete in all respect (wooden or PVC hand railing to be paid extra) with priming coat of red oxide. | C33: =GF1_MES!K430 | D33: Kg | E33: 30 | F33: P Kg | G33: =IF(C33,ROUNDUP(C33*E33,0),"")
A34: 23 | B34: Cement concrete including curing compaction etc. complete using stone aggregate 40 mm nominal size in foundation plinth, excluding the cost of shuttering, using : 1 Cement : 5 Sand : 10 aggregate Mix. (under floor) | C34: =GF1_MES!K432 | D34: Cum | E34: 850 | F34: P Cum | G34: =IF(C34,ROUNDUP(C34*E34,0),"")
A35: 24 | B35: Polished Blue Kota stone flooring skirting laid over 20 mm thick base CM 1:4 and jointed with Grey cement slurry to match the shade of the slab including rubbing and polishing complete
B36: (a) for area of each slab from 901 to 2000 sq. cm 20 mm thick slab. | C36: =GF1_MES!K437 | D36: Sqm | E36: 270 | F36: P Sqm | G36: =IF(C36,ROUNDUP(C36*E36,0),"")
B37: (b) for area of each slab from 2001 to 5000 sq. cm 20 mm thick slab. | C37: =GF1_MES!K480 | D37: Sqm | E37: 300 | F37: P Sqm | G37: =IF(C37,ROUNDUP(C37*E37,0),"")
A38: 25 | B38: Supplying and fixing in wall machine cut and polished stone shelves, tands and sills in cement mortar 1:3 with machine cut edge. | G38: =IF(C38,ROUNDUP(C38*E38,0),"")
B39: (A) Kota stone 25 to 30 mm thick | C39: =GF1_MES!K505 | D39: Sqm | E39: 295 | F39: P Sqm | G39: =IF(C39,ROUNDUP(C39*E39,0),"")
B40: (B) Sand or other approved stone 50 mm thick | C40: =GF1_MES!K510 | D40: Sqm | E40: 255 | F40: P Sqm | G40: =IF(C40,ROUNDUP(C40*E40,0),"")
...

Sheet GF1_MES
A1: ='gen-abstract'!A2
A2: PART 'A' CIVIL WORK GROUND FLOOR
A3: DETAILS OF MEASUREMENTS
A4: S.N. | B4: Particulars | C4: Nos. | E4: Length | G4: Breadth | I4: Height | K4: Qty. | L4: Units
B5: Center to center distances
B6: Ground Floor
B7: Main walls 300 mm th. in Y Direction
B8: LS Garage | C8: 2 | D8: x | E8: 9.23 | J8: = | K8: =IF(C8,C8*E8,"") | L8: RM
B9: LS Library | C9: 1 | D9: x | E9: 3.51 | J9: = | K9: =IF(C9,C9*E9,"") | L9: RM
B10: RS Staircase | C10: 1 | D10: x | E10: 3.97 | J10: = | K10: =IF(C10,C10*E10,"") | L10: RM
B11: RS Library | C11: 1 | D11: x | E11: 6.86 | J11: = | K11: =IF(C11,C11*E11,"") | L11: RM
B12: RS Kitchen | C12: 1 | D12: x | E12: 4.58 | J12: = | K12: =IF(C12,C12*E12,"") | L12: RM
B13: RS Living | C13: 1 | D13: x | E13: 5.19 | J13: = | K13: =IF(C13,C13*E13,"") | L13: RM
B14: RS Dining | C14: 1 | D14: x | E14: 4.88 | J14: = | K14: =IF(C14,C14*E14,"") | L14: RM
B15: LS Toilets | C15: 1 | D15: x | E15: 6.41 | J15: = | K15: =IF(C15,C15*E15,"") | L15: RM
B16: RS Bed | C16: 1 | D16: x | E16: 14.94 | J16: = | K16: =IF(C16,C16*E16,"") | L16: RM
B17: Platform Front | C17: 2 | D17: x | E17: 0.92 | J17: = | K17: =IF(C17,C17*E17,"") | L17: RM
B18: Platform Back | C18: 2 | D18: x | E18: 0.61 | J18: = | K18: =IF(C18,C18*E18,"") | L18: RM
B19: Main walls 300 mm th. in X Direction
B20: Garage | C20: 2 | D20: x | E20: 3.05 | J20: = | K20: =IF(C20,C20*E20,"") | L20: RM
B21: Library | C21: 1 | D21: x | E21: 3.66 | J21: = | K21: =IF(C21,C21*E21,"") | L21: RM
B22: Staircase | C22: 1 | D22: x | E22: 2.75 | J22: = | K22: =IF(C22,C22*E22,"") | L22: RM
B23: Kitchen | C23: 2 | D23: x | E23: 3.97 | J23: = | K23: =IF(C23,C23*E23,"") | L23: RM
B24: Living | C24: 3 | D24: x | E24: 4.27 | J24: = | K24: =IF(C24,C24*E24,"") | L24: RM
B25: Bed | C25: 4 | D25: x | E25: 4.27 | J25: = | K25: =IF(C25,C25*E25,"") | L25: RM
B26: Platform Front | C26: 1 | D26: x | E26: 2.75 | J26: = | K26: =IF(C26,C26*E26,"") | L26: RM
B27: Platform Back | C27: 1 | D27: x | E27: 4.27 | J27: = | K27: =IF(C27,C27*E27,"") | L27: RM
I28: TOTAL | J28: = | K28: =SUM(K8:K27) | L28: RM
B29: First Floor
B30: Main walls 300 mm th. in X &Y Direction
B31: LS Bed | C31: 2 | D31: x | E31: 6.41 | J31: = | K31: =IF(C31,C31*E31,"") | L31: RM
B32: Bed | C32: 1 | D32: x | E32: 4.58 | J32: = | K32: =IF(C32,C32*E32,"") | L32: RM
I33: TOTAL | J33: = | K33: =SUM(K31:K32) | L33: RM
B34: PARAPET WALL300 MM
B35: FF | C35: 2 | D35: x | E35: 12.35 | J35: = | K35: =IF(C35,C35*E35,"") | L35: RM
C36: 2 | D36: x | E36: 8.23 | J36: = | K36: =IF(C36,C36*E36,"") | L36: RM
B37: GF | C37: 2 | D37: x | E37: 13.42 | J37: = | K37: =IF(C37,C37*E37,"") | L37: RM
C38: 2 | D38: x | E38: 14.33 | J38: = | K38: =IF(C38,C38*E38,"") | L38: RM
I39: TOTAL | J39: = | K39: =SUM(K35:K38) | L39: RM
B40: Brick Partition walls in Y Direction
...

Sheet sanitary-abs
A1: ='gen-abstract'!A2
A2: PART 'B' SANITARY & WATER SUPPLY WORK
A3: ABSTRACT OF COST
A4: S.No. | B4: Particulars. | C4: Quantity | E4: Rate | F4: Unit | G4: Amount
A5: 1 | B5: P & F Indian Type white glazed vitreous china Ist quality WC Orissa Pan (IS : 2556 Mark) with 100 mm vitreous china P or S trap including cutting and making good the wall and floor. Size 580x440 mm | C5: 2 | D5: Nos. | E5: 890 | F5: Each | G5: =IF(C5,ROUNDUP(C5*E5,0),"")
A6: =A5+1 | B6: P & F Flush cock/Flush valve (IS : 9758 Mark) for WC of approved quality make : C.P. Brass concealed 25 mm | C6: 2 | D6: Nos. | E6: 650 | F6: Each | G6: =IF(C6,ROUNDUP(C6*E6,0),"")
A7: =IF(A6,A6+1,#REF!+1) | B7: P & F WVC wash basin (Ist quality, IS : 2556 Mark) of approved make with C.I. brackets duly painted 1 No. 15 mm C.P. Pillar cock (IS : 8934 Mark) & 32 mm C.P. Brass waste coupling of approved make, 25 mm G.I. waste pipe complete including cutting and making good the wall size 580mmx450mm. | C7: 4 | D7: Nos. | E7: 1250 | F7: Each | G7: =IF(C7,ROUNDUP(C7*E7,0),"")
A8: =IF(A7,A7+1,A6+1) | B8: P&F beveled edge mirror of special glass of approved make (Atul or equivalent) complete with 6 mm thick Asbestos Cement sheet ground fixed to wooden screws & washers sizes 600 x 450 mm x 4 mm thick. | C8: 4 | D8: Nos. | E8: 210 | F8: Each | G8: =IF(C8,ROUNDUP(C8*E8,0),"")
A9: =IF(A8,A8+1,A7+1) | B9: P & F grating of approved/quality make : Cast iron. | C9: 8 | D9: Nos. | E9: 30 | F9: Each | G9: =IF(C9,ROUNDUP(C9*E9,0),"")
A10: =IF(A9,A9+1,A8+1) | B10: P & F GI Pipes (Internal work) with G.I. fittings (IS : 1239 Mark) & MS clamps, including cutting and making good the wall and floors : | G10: =IF(C10,ROUNDUP(C10*E10,0),"")
A11: A. | B11: 15 mm Dai nominal bore `B’ Class. | C11: =sanitary_MEASUR!K22 | D11: RM | E11: 70 | F11: P RM | G11: =IF(C11,ROUNDUP(C11*E11,0),"")
A12: B. | B12: 25 mm Dai nominal bore `B’ Class | C12: =sanitary_MEASUR!K27 | D12: RM | E12: 117 | F12: P RM | G12: =IF(C12,ROUNDUP(C12*E12,0),"")
A13: 7 | B13: P & F GI Pipes (External work) with G.I. fittings (IS : 1239 Mark) , including trenching and refilling earth etc. : | G13: =IF(C13,ROUNDUP(C13*E13,0),"")
A14: A. | B14: 25 mm Dai nominal bore `B’ Class. | C14: =sanitary_MEASUR!K32 | D14: RM | E14: 98 | F14: P RM | G14: =IF(C14,ROUNDUP(C14*E14,0),"")
A15: =A13+1 | B15: Making connection of G.I. distribution branch with G.I. main including all fittings . (a) upto 25 mm Dai. | C15: =sanitary_MEASUR!K35 | D15: Nos. | E15: 100 | F15: Each | G15: =IF(C15,ROUNDUP(C15*E15,0),"")
A16: 9 | B16: P & F Bib Cock (IS : 8931 Mark) superior quality of approved make : Brass 400 gram 15 mm | C16: 15 | D16: Nos. | E16: 120 | F16: Each | G16: =IF(C16,ROUNDUP(C16*E16,0),"")
A17: =IF(A16,A16+1,#REF!+1) | B17: P & F Stop Cock (IS : 8931 Mark) superior quality of approved make : Brass 400 gram 15 mm | C17: 5 | D17: Nos. | E17: 120 | F17: Each | G17: =IF(C17,ROUNDUP(C17*E17,0),"")
A18: 11 | B18: P/F full way valve (IS:778 Mark) or wheel valve of approved make: gun metal | G18: =IF(C18,ROUNDUP(C18*E18,0),"")
B19: (A) 15 mm | C19: 2 | D19: Nos. | E19: 150 | F19: Each | G19: =IF(C19,ROUNDUP(C19*E19,0),"")
B20: (B) 25 mm | C20: 2 | D20: Nos. | E20: 300 | F20: Each | G20: =IF(C20,ROUNDUP(C20*E20,0),"")
A21: =IF(A18,A18+1,#REF!+1) | B21: P & F PVC Storage Tank confirming to IS standards of approved make with cover, 25 mm Dai 1 M long C.I. over flow pipe & 25 cm. long wash out pipe with plug and socket, including making connection, etc. complete of approved design: | G21: =IF(C21,ROUNDUP(C21*E21,0),"")
B22: (A) 1000 (litres capacity). | C22: 4 | D22: Nos. | E22: =5000 | F22: Each | G22: =IF(C22,ROUNDUP(C22*E22,0),"")
A23: =IF(A21,A21+1,A18+1) | B23: P & F Ball Cock (IS : 1703 Mark) with Rod & PVC Ball complete : | G23: =IF(C23,ROUNDUP(C23*E23,0),"")
B24: (A) Brass wt. 400 gram 15 mm. | C24: 4 | D24: Nos. | E24: 150 | F24: Each | G24: =IF(C24,ROUNDUP(C24*E24,0),"")
A25: =IF(A23,A23+1,A21+1) | B25: Providing and fixing Unplasticized Poly Vinyl Chloride (UPVC) SWR pipes type B for soil and rain and waste discharge system (IS:13592 : 1992 marked) of approved quality/ make including jointing the pipes complete. | G25: =IF(C25,ROUNDUP(C25*E25,0),"")
B26: (A) 110 mm dia. | C26: =sanitary_MEASUR!K59 | D26: RM | E26: =200 | F26: P RM | G26: =IF(C26,ROUNDUP(C26*E26,0),"")
A27: 15 | B27: Providing and fixing Unplasticized Poly Vinyl Chloride (UPVC) SWR pipe fittings type B for soil and rain and waste discharge system (IS:13592 : 1992 marked) of approved quality/ make including jointing the pipes complete. | G27: =IF(C27,ROUNDUP(C27*E27,0),"")
A28: A. | B28: 110 mm dia. Offset | C28: 1 | D28: Nos. | E28: 162 | F28: Each | G28: =IF(C28,ROUNDUP(C28*E28,0),"")
A29: B. | B29: 110 mm dia. Coupler | C29: 5 | D29: Nos. | E29: 62 | F29: Each | G29: =IF(C29,ROUNDUP(C29*E29,0),"")
A30: C. | B30: 110 mm dia. Single 'Y' with Door | C30: 1 | D30: Nos. | E30: 199 | F30: Each | G30: =IF(C30,ROUNDUP(C30*E30,0),"")
A31: D. | B31: 100 mm dia. vent Cowl | C31: =sanitary_MEASUR!K64 | D31: Nos. | E31: 34 | F31: Each | G31: =IF(C31,ROUNDUP(C31*E31,0),"")
A32: E. | B32: 110 mm dia. Single 'Y' | C32: 1 | D32: Nos. | E32: 159 | F32: Each | G32: =IF(C32,ROUNDUP(C32*E32,0),"")
A33: F. | B33: 110 mm dia. door Bend | C33: 1 | D33: Nos. | E33: 111 | F33: Each | G33: =IF(C33,ROUNDUP(C33*E33,0),"")
A34: G. | B34: 110 mm dia. Bend 87.5 degree. | C34: 1 | D34: Nos. | E34: 89 | F34: Each | G34: =IF(C34,ROUNDUP(C34*E34,0),"")
A35: 16 | B35: Providing and fixing Spun Cast Iron (SCI ) Floor Trap (Nahni) of (IS : 3789mark) approved quality /make with socket down or hinged grating including cutting and making good the floor :- size 100x100 mm. | C35: 4 | D35: Nos. | E35: 140 | F35: Each | G35: =IF(C35,ROUNDUP(C35*E35,0),"")
A36: 17 | B36: Construction of manhole in all types of soil inner size 90 x 60 Cm with 300 mm thick masonry in CM 1:6, 10 cm. thick cement concrete 1:5:10 in foundation, 20 mm thick inside plaster in CM 1:6, finished with floating neat cement, 50 mm thick M-15 grade CC flooring, making channels, 80 mm thick stone slab covering with 40 mm thick M-15 grade C.C. flooring, 25 Kg CI cover with frame of 450 mm Dai. earth work etc. Complete as per approved drawing including disposal of surplus earth within a lead of 50 m. | G36: =IF(C36,ROUNDUP(C36*E36,0),"")
B37: (A) Depth upto 0.5 M | C37: 3 | D37: Nos. | E37: 1500 | F37: Each | G37: =IF(C37,ROUNDUP(C37*E37,0),"")
B38: (B) Depth 0.5 M to 1.0 M | C38: 3 | D38: Nos. | E38: 2050 | F38: Each | G38: =IF(C38,ROUNDUP(C38*E38,0),"")
A39: =IF(A36,A36+1,#REF!+1) | B39: Supplying and fixing C.I. cover with frame, C.I. gratings for chambers & man holes. | C39: =sanitary_MEASUR!K72 | D39: Kg. | E39: 12 | F39: P Kg. | G39: =IF(C39,ROUNDUP(C39*E39,0),"")
A40: 19 | B40: Providing laying and jointing glazed SW pipes Grade `A’ (IS : 651 marked) of approved make with spun yarn & stiff mixture of cement mortar 1:1 excavation and refilling of earth in all types of soil upto 1.2m depth, SW fittings, including testing of joints etc. complete 100 mm dia. | C40: 40 | D40: RM | E40: 95 | F40: P RM | G40: =IF(C40,ROUNDUP(C40*E40,0),"")
...

Sheet sanitary_MEASUR
A1: ='gen-abstract'!A2
A2: PART 'B' SANITARY & WATER SUPPLY WORK
A3: DETAILS OF MEASUREMENTS
A4: S.N. | B4: Particulars | C4: Nos. | E4: Length | G4: Breadth | I4: Height | K4: Qty. | L4: Units
A5: 1 | B5: P & F Indian Type white glazed vitreous china Ist quality WC Orissa Pan (IS : 2556 Mark) with 100 mm vitreous china P or S trap including cutting and making good the wall and floor. Size 580x440 mm
C6: 6 | D6: x | E6: 1 | J6: =IF(K6,"=","") | K6: =C6*E6 | L6: Nos.
A7: =A5+1 | B7: P & F Flush cock/Flush valve (IS : 9758 Mark) for WC of approved quality make : C.P. Brass concealed 25 mm | J7: =IF(K7,"=","")
C8: 6 | D8: x | E8: 1 | J8: =IF(K8,"=","") | K8: =C8*E8 | L8: Nos.
H9: Total | J9: =IF(K9,"=","") | K9: =SUM(K8:K8) | L9: Nos.
A10: =IF(A7,A7+1,A5+1) | J10: =IF(K10,"=","")
C11: 5 | D11: x | E11: 1 | J11: =IF(K11,"=","") | K11: =C11*E11 | L11: Nos.
H12: Total | J12: =IF(K12,"=","") | K12: =SUM(K11:K11) | L12: Nos.
A13: =IF(A10,A10+1,A7+1) | B13: P&F beveled edge mirror of special glass of approved make (Atul or equivalent) complete with 6 mm thick Asbestos Cement sheet ground fixed to wooden screws & washers sizes 600 x 450 mm x 4 mm thick. | C13: =K12 | D13: x | E13: 1 | J13: =IF(K13,"=","") | K13: =C13*E13 | L13: Nos.
A15: 5 | B15: P & F grating of approved/quality make : Cast iron. | J15: =IF(K15,"=","")
B16: G.F. | C16: 11 | D16: x | E16: 1 | J16: =IF(K16,"=","") | K16: =C16*E16 | L16: Nos.
H17: Total | J17: =IF(K17,"=","") | K17: =SUM(K16:K16) | L17: Nos.
A18: 6 | B18: P & F GI Pipes (Internal work) with G.I. fittings (IS : 1239 Mark) & MS clamps, including cutting and making good the walls and floors : | J18: =IF(K18,"=","")
A19: A. | B19: 15 mm dia nominal bore `B’ Class. | J19: =IF(K19,"=","")
B20: W.C. Internal plumbing | C20: 5 | D20: x | E20: 4.5 | J20: =IF(K20,"=","") | K20: =C20*E20 | L20: RM
B21: W.B. Internal plumbing | C21: 5 | D21: x | E21: 4.5 | J21: =IF(K21,"=","") | K21: =C21*E21 | L21: RM
H22: Total | J22: =IF(K22,"=","") | K22: =SUM(K19:K21) | L22: RM
A23: B. | B23: 25 mm dia nominal bore `B’ Class | J23: =IF(K23,"=","")
B24: Uptake pipes | C24: 4 | D24: x | E24: 16.8 | J24: =IF(K24,"=","") | K24: =C24*E24 | L24: RM
B25: Down take | C25: 4 | D25: x | E25: 14.6 | J25: =IF(K25,"=","") | K25: =C25*E25 | L25: RM
B26: Down take for W.C. | C26: 4 | D26: x | E26: 8.7 | J26: =IF(K26,"=","") | K26: =C26*E26 | L26: RM
H27: Total | J27: =IF(K27,"=","") | K27: =SUM(K23:K26) | L27: RM
A28: =A18+1 | B28: P & F GI Pipes (External work) with G.I. fittings (IS : 1239 Mark) , including trenching and refilling earth etc. : | J28: =IF(K28,"=","")
A29: A. | B29: 25 mm dia nominal bore `B’ Class. | J29: =IF(K29,"=","")
B30: From OHT/ Sump | C30: 1 | D30: x | E30: 10 | J30: =IF(K30,"=","") | K30: =C30*E30 | L30: RM
B31: Ring main | C31: 2 | D31: x | E31: 10 | J31: =IF(K31,"=","") | K31: =C31*E31 | L31: RM
H32: Total | J32: =IF(K32,"=","") | K32: =SUM(K30:K31) | L32: RM
A33: =A28+1 | B33: Making connection of G.I. distribution branch with G.I. main including all fittings . (a) upto 25 mm dia. | J33: =IF(K33,"=","")
B34: Toilets | C34: 6 | D34: x | E34: 3 | J34: =IF(K34,"=","") | K34: =C34*E34 | L34: Nos.
H35: Total | J35: =IF(K35,"=","") | K35: =SUM(K34:K34) | L35: Nos.
A36: =A33+1 | B36: P & F Bib Cock (IS : 8931 Mark) superior quality of approved make : Brass 400 gram 15 mm | J36: =IF(K36,"=","")
B37: W.C. | C37: 12 | D37: x | E37: 1 | J37: =IF(K37,"=","") | K37: =C37*E37 | L37: Nos.
B38: Court Yard | C38: 6 | D38: x | E38: 1 | J38: =IF(K38,"=","") | K38: =C38*E38 | L38: Nos.
H39: Total | J39: =IF(K39,"=","") | K39: =SUM(K37:K38) | L39: Nos.
A40: =IF(A36,A36+1,#REF!+1) | B40: P & F Stop Cock (IS : 8931 Mark) superior quality of approved make : Brass 400 gram 15 mm | J40: =IF(K40,"=","")
B41: W.B. | C41: 5 | D41: x | E41: 1 | J41: =IF(K41,"=","") | K41: =C41*E41 | L41: Nos.
...
