Workbook

Sheet gen-abstract
A2: NAME OF WORK :- Construction of Block Level Library Building at Vakhatpura, PS- Arthuna
A4: GENERAL ABSTRACT OF COST
B6: PART 'A' CIVIL WORK GROUND FLOOR | F6: Rs. | G6: =ROUND(GF1_ABS!G37,0)
B8: PART 'B' CIVIL WORK FIRST FLOOR | F8: Rs. | G8: =ROUND(FF_ABS!G30,0)
F10: TOTAL Rs. | G10: =SUM(G6:G8)
B12: PART 'C' ELECTRIC WORK @ 15% OF Civil Work | F12: Rs. | G12: =ROUND((G10)*0.15,0)
B14: Add for Contingencies @ 3% | F14: Rs. | G14: =ROUND(G10*0.03,0)
B16: Add for Quality Assurance @ 1 % | F16: Rs. | G16: =ROUND(G10*0.01,0)
B18: Add for W.C. Establishment @ 2% | F18: Rs. | G18: =ROUND(G10*0.02,0)
B20: Add Lump Sum for Electric Fixtures | G20: 75000
B22: Add Lump Sum for Furniture | G22: 175000
E23: GRAND TOTAL Rs. | G23: =SUM(G10:G22)
F25: SAY Rs. | G25: =ROUND(G23/100000,2)
G26: Lacs.
E29: CHARTERED ENGINEER,
E30: RKS TECHNO-LEGAL CONSULTANTS, UDAIPUR

Sheet GF1_ABS
A1: ='gen-abstract'!A2
A3: PART 'A' CIVIL WORK BASEMENT, GROUND FLOOR
A4: ABSTRACT OF COST
A5: S.No. | B5: Particulars. | C5: Quantity | E5: Rate | F5: Unit | G5: Amount
A6: 1 | B6: Earth work in excavation by mechanical means (Hydraulic Excavator )/ manual means in foundation trenches or drains (not exceeding 1.5 m in width or 10 sqm on plan) including dressing of sides and ramming of bottoms, lift upto 1.5 m, including taking out the excavated soil and depositing and refilling of jhiri with watering & ramming and disposal of surplus excavated soil as directed with in a lead of 50 meter. All kinds of soils | C6: =GF1_MES!K27 | D6: Cum | E6: 204.7 | F6: P Cum | G6: =C6*E6
A7: =LOOKUP(2,1/(A$1:A6<>""),A$1:A6)+1 | B7: Filling available excavated earth (excluding rock) in trenches, plinth side of foundation etc. in layers not exceeding 20 cm. in depth , consolidating each deposited layer by ramming and watering including lead upto 50Mtr. and lift upto 1.5Mtr. | C7: =GF1_MES!K33 | D7: Cum | E7: 73.6 | F7: P Cum | G7: =C7*E7
A8: =LOOKUP(2,1/(A$1:A7<>""),A$1:A7)+1 | B8: Providing and laying in position cement concrete including curing compaction etc. of specified grade excluding the cost of centering and shuttering =All up to plinth leve 1:4:8 (1Cement :4 Coarse Sand :8 Graded stone aggregate 40 mm nominal size | C8: =GF1_MES!K38 | D8: Cum | E8: 3797.3 | F8: P Cum | G8: =C8*E8
A9: =LOOKUP(2,1/(A$1:A8<>""),A$1:A8)+1 | B9: Providing and laying in position specified grade of reinforcement cement concrete all RCC structural elements upto plinth level including curing compaction finishing with rendering in cement sand mortar 1:3 ( 1 cement : 3 coarse sand) and making good the joints excluding the cost of centering shuttering and reinforcementlevel. M25 grade Design mix | C9: =GF1_MES!K43 | D9: Cum | E9: =4934+69 | F9: P Cum | G9: =C9*E9
A10: =LOOKUP(2,1/(A$1:A9<>""),A$1:A9)+1 | B10: Centering and shuttering with plywood or steel sheets including strutting, propping, bracing both ways and removal of formwork for foundations in basements rafts, footings, strap beams, bases of columns , etc. up to plinth level. | C10: =GF1_MES!K47 | D10: Sqm | E10: 180.55 | F10: P Sqm | G10: =C10*E10
A11: =LOOKUP(2,1/(A$1:A10<>""),A$1:A10)+1 | B11: Providing and layin in position specified grade of cement concrete for RCC Structure elements unto floor three level including curing, compaction, finishing with rendering in cement sand mortar 1:3 (1 cement ; 3 coarse sand) and making good the joints excluding the cost of centering shuttering and reinforcement forshuttering and reinforcement : M25 grade Design mix | C11: =GF1_MES!K56 | D11: Cum | E11: 5962.75 | F11: P Cum | G11: =C11*E11
A12: =LOOKUP(2,1/(A$1:A11<>""),A$1:A11)+1 | B12: Providing and laying in position specified grade of cement concrete for RCC structural elements upto floor five level including curing, compaction, finishing with rendering in cement sand mortar 1:3 (1 cement: 3 coarse sand) and making good the joints and cost of plastizers (if required ) excluding the cost of centering, shuttering and reinforcement for Walls (any thickness) including attached pilasters, buttresses, plinth and string courses, fillets, columns, pillars, piers, abutments, posts and struts etc. M20 grade Nominal Mix / Design Mix | C12: =GF1_MES!K59 | D12: Cum | E12: 6450.35 | F12: P Cum | G12: =C12*E12
A13: =LOOKUP(2,1/(A$1:A12<>""),A$1:A12)+1 | B13: Centering & shuttering with ply wood or steel sheets including shuttering , propping, barcing both waves with widen members and removal of form work up to floor three level for:
B14: (A) Suspended floors, roofs, landings, staircases, balconies, girders, cantilevers, bands , coping, bed plates, anchor blocks, sills, chhajjas lintel, beam etc. | C14: =GF1_MES!K73 | D14: Sqm | E14: 391 | F14: P Sqm | G14: =C14*E14
B15: (B) Columns, pillars, posts and struts etc. | C15: =GF1_MES!K77 | D15: Sqm | E15: 431.25 | F15: P Sqm | G15: =C15*E15
A16: =LOOKUP(2,1/(A$1:A15<>""),A$1:A15)+1 | B16: Providing and fabricating reinforcement for R.C.C. work including straightening, cutting, bending, placing in position and binding (including cost of binding wire) all complete up to floor three level. Tremo Mechanically treated bars | C16: =GF1_MES!K82 | D16: Kg | E16: 88.55 | F16: P Kg | G16: =C16*E16
A17: =LOOKUP(2,1/(A$1:A16<>""),A$1:A16)+1 | B17: Brick work with F.P.S. bricks of class designation 75 in superstructure above plinth level upto floor V level in all shapes and sizes in : : Cement mortar 1 : 6 (1 cement : 6 coarse sand) | C17: =GF1_MES!K92 | D17: Cum | E17: 5738.5 | F17: P Cum | G17: =C17*E17
A18: =LOOKUP(2,1/(A$1:A17<>""),A$1:A17)+1 | B18: Half brick masonry in Superstructure , above plinth level upto floor V level using bricks of designation 75 in Cement mortar 1 : 4 (1 cement : 4 coarse sand) | C18: =GF1_MES!K95 | D18: Sqm | E18: 604.9 | F18: P Sqm | G18: =C18*E18
A19: =LOOKUP(2,1/(A$1:A18<>""),A$1:A18)+1 | B19: Random Rubble stone masonry for foundation and plinth in Cement Sand mortar above 30 CM thick wall in: Cement Mortar 1:6 ( 1-Cement : 6-Sand). | C19: =GF1_MES!K97 | D19: Cum | E19: 3263.7 | F19: P Cum | G19: =C19*E19
A20: =LOOKUP(2,1/(A$1:A19<>""),A$1:A19)+1 | B20: Plaster on new surface on walls in cement sand mortar 1:6 including raking of joints etc. complete fine finished : 20 mm thick. | C20: =GF1_MES!K117 | D20: Sqm | E20: 218.5 | F20: P Sqm | G20: =IF(C20,ROUNDUP(C20*E20,0),"")
A21: =LOOKUP(2,1/(A$1:A20<>""),A$1:A20)+1 | B21: 6 mm cement plaster to ceiling of mix 1 : 3 ( 1 cement : 3 fine - sand ) | C21: =GF1_MES!K122 | D21: Sqm | E21: 159.85 | F21: P Sqm | G21: =IF(C21,ROUNDUP(C21*E21,0),"")
A22: =LOOKUP(2,1/(A$1:A21<>""),A$1:A21)+1 | B22: Making grooves as per design in plaster 10mm to 20mm wide. | C22: =GF1_MES!K126 | D22: RM | E22: 7 | F22: P RM | G22: =IF(C22,ROUNDUP(C22*E22,0),"")
A23: =LOOKUP(2,1/(A$1:A22<>""),A$1:A22)+1 | B23: Applying plaster of Paris or lime putty sandala over cement plaster surface for making even surface. | C23: =GF1_MES!K129 | D23: Sqm | E23: 96.6 | F23: P Sqm | G23: =IF(C23,ROUNDUP(C23*E23,0),"")
A24: =LOOKUP(2,1/(A$1:A23<>""),A$1:A23)+1 | B24: Providing and fixing T-iron/angle iron frames for doors windows and ventilators of mild steel tee or angle sections joints mitered and welded with 15 x 3 mm lugs, 10 cm. long embedded in cement concrete blocks 15x15x10 cm. size of 1:3:6 (1 cement : 3 coarse sand : 6 graded stone aggregate 20 mm nominal size) or with wooden plugs and screws or rawl plugs and screws or with fixing clips and screws or with bolt and nuts as required including fixing of necessary butt hinges and screws and applying a priming coat of approved steel primer. | C24: =GF1_MES!K133 | D24: Kg | E24: 95.45 | F24: P Kg | G24: =C24*E24
A25: =LOOKUP(2,1/(A$1:A24<>""),A$1:A24)+1 | B25: Providing & fixing steel glazed doors, windows and ventilators shutters of standred rolled steel section joint mitred and welded with steel 13x3mm lugs 10 Cm. long embedded in cement concrete blocks 15x10x10 Cm. of 1:3:6 (1-Cement:3-coarse sand:6-graded stone aggregate 20 mm nominal size) or with wooden plugs and screws or rawl plugs and screws or with fixing clips or with bolts and nuts as required, including providing and fixing of plain glass panes 4mm thick with copper glazing clips and special metal-sash putty of approved make, or metal beading with screws complete including priming coat of approved steel primer, excluding the cost of metal beading and other fittings except necessary hinges of pivots steel handles and peg stay etc. as required. Patially fixed and partially openable fixed area not exceed 33% | C25: =GF1_MES!K136 | D25: Sqm | E25: 3553.5 | F25: P Sqm | G25: =C25*E25
A26: =LOOKUP(2,1/(A$1:A25<>""),A$1:A25)+1 | B26: Supplying and fixing fixed wire gauge of 14 mesh x 24 gauge to the metal frame of rolled section by metal beading 20x3mm with suitable screw at not exceeding 150 mm distance. | C26: =GF1_MES!K143 | D26: Sqm | E26: 709.55 | F26: P Sqm | G26: =C26*E26
A27: =LOOKUP(2,1/(A$1:A26<>""),A$1:A26)+1 | B27: Supply and fixing in cement mortar welded hand railing made out of M.S. round or square bars, flats etc. for staircase or verandah as per design complete in all respect (wooden or PVC hand railing to be paid extra) with priming coat of red oxide. | C27: =GF1_MES!K158 | D27: Kg | E27: 93.15 | F27: P Kg | G27: =C27*E27
A28: =LOOKUP(2,1/(A$1:A27<>""),A$1:A27)+1 | B28: 30mm thick factory made solid panel PVC door shutter consisting of frame made out of M.S. tubes of 19 gauge thickness and size of 19mm x 19mm for stiles and 15 mm x15mm , top & bottom rails. M.S .frame shall have a coat of steel primers of approved make and manufacture M.S. frame covered with 5mm thick heat moulded PVC ‘C channel of size 30mm thickness, 70mm width out of which 50mm shall be flat and 20mm shall be tapered in 45 degree angle on either side forming stiles; and 5mm thick, 95mm wide PVC sheet out of which 75 mm shall be flat and 20mm shall be tapered in 45 degree on the inner side to form top and bottom rail and 115mm wide PVC sheet out of which 75 mm shall be flat and 20mm shall be tapered on both sides to form lock rail. Top bottom and lock rails shall be provided either side of the panel. 10mm (5mm x 2) thick, 20mm wide cross PVC sheet shall be provided as gap insert for top rail & bottom rail. Panelling of 5mm thick PVC sheet to be fitted in the M.S. frame welded/ sealed to the stiles & rails with 7mm (5mm +2mm) thick x 15mm wide PVC sheet bending on inner side, | C28: =GF1_MES!K161 | D28: Sqm | E28: 3849.05 | F28: P Sqm | G28: =C28*E28
A29: =LOOKUP(2,1/(A$1:A28<>""),A$1:A28)+1 | B29: Providing and fixing Square bars or other flat welded to window, ventilators etc. | C29: =GF1_MES!K140 | D29: Kg | E29: 74.75 | F29: P Kg | G29: =C29*E29
A30: =LOOKUP(2,1/(A$1:A29<>""),A$1:A29)+1 | B30: Polished Blue Kota Stone flooring skirting, laid over 20 mm thick base of C.M. 1:4 and jointed with grey cement slurry to match the shade of the slab including rubbing and polishing complete : For area of each slab up to 2001 to 5000 Sq. Cm : (A) 25 mm thick slab. | C30: =GF1_MES!K146 | D30: Sqm | E30: 1176.45 | F30: P Sqm | G30: =C30*E30
A31: =LOOKUP(2,1/(A$1:A30<>""),A$1:A30)+1 | B31: Random rubble dry stone Kharanja under floor. | C31: =GF1_MES!K150 | D31: Cum | E31: 1071.8 | F31: P Cum | G31: =C31*E31
A32: =LOOKUP(2,1/(A$1:A31<>""),A$1:A31)+1 | B32: Providing and fixing Ist quality standard White Ivory Glazed Tiles ISI marked [IS:13753] of size 300mm x 200mm in walls, floors, steps, pillars etc. laid on a bed of neat cement slurry finished with flush pointing in white cement mixed with pigment to match the shade of tile complete (excluding the cost of cement plaster). Category-I : Kajariya, Jhonson, Somani make etc. | C32: =GF1_MES!K165 | D32: Sqm | E32: 775.1 | F32: P Sqm | G32: =C32*E32
A33: =LOOKUP(2,1/(A$1:A31<>""),A$1:A31)+1 | B33: White washing with lime to give an even shade including all scaffolding: New work (two or more coats). | C33: =GF1_MES!K168 | D33: Sqm | E33: 12.65 | F33: P Sqm | G33: =C33*E33
A34: =LOOKUP(2,1/(A$1:A33<>""),A$1:A33)+1 | B34: Colour washing of all shades to give an even shade including all scaffolding: New work (two or more coats) with a base coat of white washing with lime. | C34: =GF1_MES!K172 | D34: Sqm | E34: 16.1 | F34: P Sqm | G34: =C34*E34
A35: =LOOKUP(2,1/(A$1:A34<>""),A$1:A34)+1 | B35: Applying priming coat with ready mix pink or Grey primer of approved brand and manufacture on wood work hard and soft wood. | C35: =GF1_MES!K177 | D35: Sqm | E35: 33.35 | F35: P Sqm | G35: =C35*E35
A36: =LOOKUP(2,1/(A$1:A35<>""),A$1:A35)+1 | B36: Painting with enamel paint of approved brand and manufacture to give an even shade two or more coats on new work. | C36: =GF1_MES!K180 | D36: Sqm | E36: 79.35 | F36: P Sqm | G36: =C36*E36
E37: Total | F37: Rs. | G37: =SUM(G1:G36)
D40: CHARTERED ENGINEER,
D41: RKS TECHNO-LEGAL CONSULTANTS, UDAIPUR

Sheet GF1_MES
A1: ='gen-abstract'!A2
A3: PART 'A' CIVIL WORK FIRST FLOOR
A4: DETAILS OF MEASUREMENTS
A5: S.N. | B5: Particulars | C5: Nos. | E5: Length | G5: Breadth | I5: Height | K5: Qty. | L5: Units
B6: Center to center distances
B7: Ground Floor
B8: Main walls 230 mm th. in x and Y Direction
C9: 2 | D9: x | E9: 6 | J9: = | K9: =IF(C9,C9*E9,"") | L9: RM
C10: 2 | D10: x | E10: 5.1 | J10: = | K10: =IF(C9,C9*E9,"") | L10: RM
C11: 2 | D11: x | E11: 6 | J11: = | K11: =IF(C9,C9*E9,"") | L11: RM
C12: 2 | D12: x | E12: 6.9 | J12: = | K12: =IF(C9,C9*E9,"") | L12: RM
C13: 2 | D13: x | E13: 15 | J13: = | K13: =IF(C10,C10*E10,"") | L13: RM
C14: 2 | D14: x | E14: 4.33 | J14: = | K14: =IF(C9,C9*E9,"") | L14: RM
C15: 2 | D15: x | E15: 5.1 | J15: = | K15: =IF(C9,C9*E9,"") | L15: RM
C16: 2 | D16: x | E16: 5.86 | J16: = | K16: =IF(C9,C9*E9,"") | L16: RM
I17: TOTAL | J17: = | K17: =SUM(K9:K10) | L17: RM
B19: PARAPET WALL 230 MM
B20: Back Side | C20: 1 | D20: x | E20: =K11 | J20: = | K20: =IF(C14,C14*E14,"") | L20: RM
C21: 2 | D21: x | E21: 3.68 | J21: = | K21: =IF(C9,C9*E9,"") | L21: RM
C22: 2 | D22: x | E22: 4.33 | J22: = | K22: =IF(C9,C9*E9,"") | L22: RM
C23: 2 | D23: x | E23: 4.98 | J23: = | K23: =IF(C9,C9*E9,"") | L23: RM
I24: TOTAL | J24: = | K24: =SUM(K14:K14) | L24: RM
B25: Brick Partition walls in X and Y Direction
B26: Office | C26: 1 | D26: x | E26: 2.7 | J26: = | K26: =IF(C17,C17*E17,"") | L26: RM
I27: TOTAL | J27: = | K27: =SUM(K9:K10) | L27: RM
I28: TOTAL | J28: = | K28: =SUM(K9:K10) | L28: RM
I29: TOTAL | J29: = | K29: =SUM(K9:K10) | L29: RM
C30: 1 | D30: x | E30: 1.2 | J30: = | K30: =IF(C18,C18*E18,"") | L30: RM
B34: Toilet | C34: 1 | D34: x | E34: 3.6 | J34: = | K34: =IF(C19,C19*E19,"") | L34: RM
C35: 2 | D35: x | E35: 2.1 | J35: = | K35: =IF(C20,C20*E20,"") | L35: RM
I36: TOTAL | J36: = | K36: =SUM(K17:K20) | L36: RM
A38: 1 | B38: Earth work in excavation in foundation trenches or drains including dressing of sides and ramming of bottoms, lift up to 1.5 Mtr. including taking out the excavated soil and depositing and refilling of jhiri with watering & ramming and disposal of surplus excavated soil as directed within a lead of 50 meter. All kinds of soil.
B39: Footings | C39: 8 | D39: x | E39: 2.75 | F39: x | G39: 2.85 | H39: x | I39: 1.5 | J39: = | K39: =IF(C24,C24*E24*G24*I24,"") | L39: Cum
B40: Main Walls | C40: 1 | D40: x | E40: =K11 | F40: x | G40: 0.9 | H40: x | I40: 0.9 | J40: = | K40: =IF(C25,C25*E25*G25*I25,"") | L40: Cum
B41: Partition Walls | C41: 1 | D41: x | E41: =K21 | F41: x | G41: 0.9 | H41: x | I41: 0.75 | J41: = | K41: =IF(C26,C26*E26*G26*I26,"") | L41: Cum
G42: Total | K42: =SUM(K24:K26) | L42: Cum
A43: =LOOKUP(2,1/(A$1:A27<>""),A$1:A27)+1 | B43: Filling available excavated earth (excluding rock) in trenches, plinth side of foundation etc. in layers not exceeding 20 cm. in depth , consolidating each deposited layer by ramming and watering including lead upto 50Mtr. and lift upto 1.5Mtr.
B45: Walls AREA | C45: 1 | D45: x | E45: =E9-0.6 | F45: x | G45: =E10-0.6 | J45: = | K45: =IF(C30,C30*E30*G30,"") | L45: Sqm
B47: Qty. in Filling | E47: =K30 | F47: x | G47: 0.45 | J47: = | K47: =E32*G32 | L47: Cum
G48: Total | K48: =SUM(K32) | L48: Cum
...

Sheet FF_ABS
A1: ='[1]gen-abstract'!A2
A3: PART 'A' CIVIL WORK BASEMENT, GROUND FLOOR
A4: ABSTRACT OF COST
A5: S.No. | B5: Particulars. | C5: Quantity | E5: Rate | F5: Unit | G5: Amount
A6: 1 | B6: Providing and layin in position specified grade of cement concrete for RCC Structure elements unto floor three level including curing, compaction, finishing with rendering in cement sand mortar 1:3 (1 cement ; 3 coarse sand) and making good the joints excluding the cost of centering shuttering and reinforcement forshuttering and reinforcement : M25 grade Design mix | C6: =FF_MES!K56 | D6: Cum | E6: 5185 | F6: P Cum | G6: =C6*E6
A7: =LOOKUP(2,1/(A$1:A6<>""),A$1:A6)+1 | B7: Providing and laying in position specified grade of cement concrete for RCC structural elements upto floor five level including curing, compaction, finishing with rendering in cement sand mortar 1:3 (1 cement: 3 coarse sand) and making good the joints and cost of plastizers (if required ) excluding the cost of centering, shuttering and reinforcement for Walls (any thickness) including attached pilasters, buttresses, plinth and string courses, fillets, columns, pillars, piers, abutments, posts and struts etc. M25 grade Nominal Mix / Design Mix | C7: =FF_MES!K60 | D7: Cum | E7: 5609 | F7: P Cum | G7: =C7*E7
A8: =LOOKUP(2,1/(A$1:A7<>""),A$1:A7)+1 | B8: Centering & shuttering with ply wood or steel sheets including shuttering , propping, barcing both waves with widen members and removal of form work up to floor three level for:
B9: (A) Suspended floors, roofs, landings, staircases, balconies, girders, cantilevers, bands , coping, bed plates, anchor blocks, sills, chhajjas lintel, beam etc. | C9: =FF_MES!K74 | D9: Sqm | E9: 340 | F9: P Sqm | G9: =C9*E9
B10: (B) Columns, pillars, posts and struts etc. | C10: =FF_MES!K78 | D10: Sqm | E10: 375 | F10: P Sqm | G10: =C10*E10
A11: =LOOKUP(2,1/(A$1:A10<>""),A$1:A10)+1 | B11: Providing and fabricating reinforcement for R.C.C. work including straightening, cutting, bending, placing in position and binding (including cost of binding wire) all complete up to floor three level. Tremo Mechanically treated bars | C11: =FF_MES!K82 | D11: Kg | E11: 77 | F11: P Kg | G11: =C11*E11
A12: =LOOKUP(2,1/(A$1:A11<>""),A$1:A11)+1 | B12: Brick work with F.P.S. bricks of class designation 75 in superstructure above plinth level upto floor V level in all shapes and sizes in : : Cement mortar 1 : 6 (1 cement : 6 coarse sand) | C12: =FF_MES!K93 | D12: Cum | E12: 4990 | F12: P Cum | G12: =C12*E12
A13: =LOOKUP(2,1/(A$1:A12<>""),A$1:A12)+1 | B13: Plaster on new surface on walls in cement sand mortar 1:6 including raking of joints etc. complete fine finished : 20 mm thick. | C13: =FF_MES!K112 | D13: Sqm | E13: 190 | F13: P Sqm | G13: =IF(C13,ROUNDUP(C13*E13,0),"")
A14: =LOOKUP(2,1/(A$1:A13<>""),A$1:A13)+1 | B14: 6 mm cement plaster to ceiling of mix 1 : 3 ( 1 cement : 3 fine - sand ) | C14: =FF_MES!K117 | D14: Sqm | E14: 139 | F14: P Sqm | G14: =IF(C14,ROUNDUP(C14*E14,0),"")
A15: =LOOKUP(2,1/(A$1:A14<>""),A$1:A14)+1 | B15: Making grooves as per design in plaster 10mm to 20mm wide. | C15: =FF_MES!K121 | D15: RM | E15: 7 | F15: P RM | G15: =IF(C15,ROUNDUP(C15*E15,0),"")
A16: =LOOKUP(2,1/(A$1:A15<>""),A$1:A15)+1 | B16: Applying plaster of Paris or lime putty sandala over cement plaster surface for making even surface. | C16: =FF_MES!K124 | D16: Sqm | E16: 84 | F16: P Sqm | G16: =IF(C16,ROUNDUP(C16*E16,0),"")
A17: =LOOKUP(2,1/(A$1:A16<>""),A$1:A16)+1 | B17: Providing and fixing T-iron/angle iron frames for doors windows and ventilators of mild steel tee or angle sections joints mitered and welded with 15 x 3 mm lugs, 10 cm. long embedded in cement concrete blocks 15x15x10 cm. size of 1:3:6 (1 cement : 3 coarse sand : 6 graded stone aggregate 20 mm nominal size) or with wooden plugs and screws or rawl plugs and screws or with fixing clips and screws or with bolt and nuts as required including fixing of necessary butt hinges and screws and applying a priming coat of approved steel primer. | C17: =FF_MES!K128 | D17: Kg | E17: 83 | F17: P Kg | G17: =C17*E17
A18: =LOOKUP(2,1/(A$1:A17<>""),A$1:A17)+1 | B18: Providing & fixing steel glazed doors, windows and ventilators shutters of standred rolled steel section joint mitred and welded with steel 13x3mm lugs 10 Cm. long embedded in cement concrete blocks 15x10x10 Cm. of 1:3:6 (1-Cement:3-coarse sand:6-graded stone aggregate 20 mm nominal size) or with wooden plugs and screws or rawl plugs and screws or with fixing clips or with bolts and nuts as required, including providing and fixing of plain glass panes 4mm thick with copper glazing clips and special metal-sash putty of approved make, or metal beading with screws complete including priming coat of approved steel primer, excluding the cost of metal beading and other fittings except necessary hinges of pivots steel handles and peg stay etc. as required. Patially fixed and partially openable fixed area not exceed 33% | C18: =FF_MES!K131 | D18: Sqm | E18: 3090 | F18: P Sqm | G18: =C18*E18
A19: =LOOKUP(2,1/(A$1:A18<>""),A$1:A18)+1 | B19: Supplying and fixing fixed wire gauge of 14 mesh x 24 gauge to the metal frame of rolled section by metal beading 20x3mm with suitable screw at not exceeding 150 mm distance. | C19: =FF_MES!K138 | D19: Sqm | E19: 617 | F19: P Sqm | G19: =C19*E19
A20: =LOOKUP(2,1/(A$1:A19<>""),A$1:A19)+1 | B20: Providing and fixing Square bars or other flat welded to window, ventilators etc. | C20: =FF_MES!K135 | D20: Kg | E20: 65 | F20: P Kg | G20: =C20*E20
A21: =LOOKUP(2,1/(A$1:A20<>""),A$1:A20)+1 | B21: Polished Blue Kota Stone flooring skirting, laid over 20 mm thick base of C.M. 1:4 and jointed with grey cement slurry to match the shade of the slab including rubbing and polishing complete : For area of each slab up to 2001 to 5000 Sq. Cm : (A) 25 mm thick slab. | C21: =FF_MES!K141 | D21: Sqm | E21: 1023 | F21: P Sqm | G21: =C21*E21
A22: =LOOKUP(2,1/(A$1:A21<>""),A$1:A21)+1 | B22: White washing with lime to give an even shade including all scaffolding: New work (two or more coats). | C22: =FF_MES!K163 | D22: Sqm | E22: 11 | F22: P Sqm | G22: =C22*E22
A23: =LOOKUP(2,1/(A$1:A22<>""),A$1:A22)+1 | B23: Colour washing of all shades to give an even shade including all scaffolding: New work (two or more coats) with a base coat of white washing with lime. | C23: =FF_MES!K167 | D23: Sqm | E23: 14 | F23: P Sqm | G23: =C23*E23
A24: =LOOKUP(2,1/(A$1:A23<>""),A$1:A23)+1 | B24: Applying priming coat with ready mix pink or Grey primer of approved brand and manufacture on wood work hard and soft wood. | C24: =FF_MES!K172 | D24: Sqm | E24: 29 | F24: P Sqm | G24: =C24*E24
A25: =LOOKUP(2,1/(A$1:A24<>""),A$1:A24)+1 | B25: Painting with enamel paint of approved brand and manufacture to give an even shade two or more coats on new work. | C25: =FF_MES!K175 | D25: Sqm | E25: 69 | F25: P Sqm | G25: =C25*E25
A26: =LOOKUP(2,1/(A$1:A25<>""),A$1:A25)+1 | B26: Providing, hoisting and fixing up to floor five level precast reinforced concrete work in Nominal M20 grade mix including cost of required centering, shuttering, finishing, smooth with 6 mm thick cement plaster 1:3 (1 cement: 3 fine sand) on exposed surface complete excluding cost of reinforcement
B27: String courses, copings, bed plates, anchor blocks, plain window sills etc | C27: =FF_MES!K178 | D27: Cum | E27: 7030 | F27: P Cum | G27: =C27*E27
A28: =LOOKUP(2,1/(A$1:A26<>""),A$1:A26)+1 | B28: Grading roof water proofing treatment with : Cement concrete 1:2:4 (1-Cement:2-coarse sand :4-graded stone aggregate 20mm nominal size).with water proofing compound as per manufacturers specification | C28: =FF_MES!K181 | D28: Cum | E28: 4483 | F28: P Cum | G28: =C28*E28
A29: =LOOKUP(2,1/(A$1:A28<>""),A$1:A28)+1 | B29: Providing batta (gola) 75mm x 75mm in .cement concrete (1:2:4) including finished with cement mortar 1:3 as per standard design. | C29: =FF_MES!K186 | D29: Mtr | E29: 111 | F29: P RM | G29: =C29*E29
E30: Total | F30: Rs. | G30: =SUM(G1:G29)
D32: CHARTERED ENGINEER,
D33: RKS TECHNO-LEGAL CONSULTANTS, UDAIPUR

Sheet FF_MES
A1: ='[1]gen-abstract'!A2
A3: PART 'A' CIVIL WORK FIRST FLOOR
A4: DETAILS OF MEASUREMENTS
A5: S.N. | B5: Particulars | C5: Nos. | E5: Length | G5: Breadth | I5: Height | K5: Qty. | L5: Units
B6: Center to center distances
B7: Ground Floor
B8: Main walls 230 mm th. in x and Y Direction
C9: 2 | D9: x | E9: 6 | J9: = | K9: =IF(C9,C9*E9,"") | L9: RM
C10: 2 | D10: x | E10: 15 | J10: = | K10: =IF(C10,C10*E10,"") | L10: RM
I11: TOTAL | J11: = | K11: =SUM(K9:K10) | L11: RM
B13: PARAPET WALL 230 MM
B14: Back Side | C14: 1 | D14: x | E14: =K11 | J14: = | K14: =IF(C14,C14*E14,"") | L14: RM
I15: TOTAL | J15: = | K15: =SUM(K14:K14) | L15: RM
B16: Brick Partition walls in X and Y Direction
B17: Office | C17: 1 | D17: x | E17: 2.7 | J17: = | K17: =IF(C17,C17*E17,"") | L17: RM
C18: 1 | D18: x | E18: 1.2 | J18: = | K18: =IF(C18,C18*E18,"") | L18: RM
B19: Toilet | C19: 1 | D19: x | E19: 3.6 | J19: = | K19: =IF(C19,C19*E19,"") | L19: RM
C20: 2 | D20: x | E20: 2.1 | J20: = | K20: =IF(C20,C20*E20,"") | L20: RM
I21: TOTAL | J21: = | K21: =SUM(K17:K20) | L21: RM
A23: 1 | B23: Earth work in excavation in foundation trenches or drains including dressing of sides and ramming of bottoms, lift up to 1.5 Mtr. including taking out the excavated soil and depositing and refilling of jhiri with watering & ramming and disposal of surplus excavated soil as directed within a lead of 50 meter. All kinds of soil.
B24: Footings | C24: 8 | D24: x | E24: 2.75 | F24: x | G24: 2.85 | H24: x | I24: 1.5 | J24: = | K24: =IF(C24,C24*E24*G24*I24,"") | L24: Cum
B25: Main Walls | C25: 1 | D25: x | E25: =K11 | F25: x | G25: 0.9 | H25: x | I25: 0.9 | J25: = | K25: =IF(C25,C25*E25*G25*I25,"") | L25: Cum
B26: Partition Walls | C26: 1 | D26: x | E26: =K21 | F26: x | G26: 0.9 | H26: x | I26: 0.75 | J26: = | K26: =IF(C26,C26*E26*G26*I26,"") | L26: Cum
G27: Total | K27: =SUM(K24:K26) | L27: Cum
A28: =LOOKUP(2,1/(A$1:A27<>""),A$1:A27)+1 | B28: Filling available excavated earth (excluding rock) in trenches, plinth side of foundation etc. in layers not exceeding 20 cm. in depth , consolidating each deposited layer by ramming and watering including lead upto 50Mtr. and lift upto 1.5Mtr.
B30: Walls AREA | C30: 1 | D30: x | E30: =E9-0.6 | F30: x | G30: =E10-0.6 | J30: = | K30: =IF(C30,C30*E30*G30,"") | L30: Sqm
B32: Qty. in Filling | E32: =K30 | F32: x | G32: 0.45 | J32: = | K32: =E32*G32 | L32: Cum
G33: Total | K33: =SUM(K32) | L33: Cum
A34: =LOOKUP(2,1/(A$1:A33<>""),A$1:A33)+1 | B34: Providing and laying in position cement concrete including curing compaction etc. of specified grade excluding the cost of centering and shuttering =All up to plinth leve 1:4:8 (1Cement :4 Coarse Sand :8 Graded stone aggregate 40 mm nominal size
B35: Main Walls | C35: 1 | D35: x | E35: =E25 | F35: x | G35: =G25 | H35: x | I35: 0.15 | J35: = | K35: =IF(C35,C35*E35*G35*I35,"") | L35: Cum
B36: Partition Walls | C36: 1 | D36: x | E36: =E26 | F36: x | G36: =G26 | H36: x | I36: 0.15 | J36: = | K36: =IF(C36,C36*E36*G36*I36,"") | L36: Cum
B37: FOOTING F1 | C37: =C24 | D37: x | E37: =E24 | F37: x | G37: =G24 | H37: x | I37: 0.3 | J37: = | K37: =IF(C37,C37*E37*G37*I37,"") | L37: Cum
G38: Total Qty. | K38: =SUM(K35:K37) | L38: Cum
A39: =LOOKUP(2,1/(A$1:A38<>""),A$1:A38)+1 | B39: Providing and laying in position specified grade of reinforcement cement concrete all RCC structural elements upto plinth level including curing compaction finishing with rendering in cement sand mortar 1:3 ( 1 cement : 3 coarse sand) and making good the joints excluding the cost of centering shuttering and reinforcementlevel. M25 grade Design mix
B40: Plinth Beams | C40: 1 | D40: x | E40: 42 | F40: x | G40: 0.23 | H40: x | I40: 0.23 | J40: = | K40: =IF(C40,C40*E40*G40*I40,"") | L40: Cum
B41: FOOTING F1 | C41: 4 | D41: x | E41: 2 | F41: x | G41: 2 | H41: x | I41: 0.5 | J41: = | K41: =IF(C41,C41*E41*G41*I41,"") | L41: Cum
B42: FOOTING F2 | C42: 4 | D42: x | E42: =E37-0.3 | F42: x | G42: =G37-0.3 | H42: x | I42: 0.83 | J42: = | K42: =IF(C42,C42*E42*G42*I42,"") | L42: Cum
G43: Total Qty. | K43: =SUM(K40:K42) | L43: Cum
A44: =LOOKUP(2,1/(A$1:A43<>""),A$1:A43)+1 | B44: Centering & shuttering with plywood or steel sheets including strutting propping, bracing both ways with wooden members and removal of form work for superstructure upto 4.5 Mtr. height above plinth level (A) For Columns, Pillars, Posts and Struts etc.
B45: Footing | C45: 8 | D45: x | E45: =2*(E42+G42) | F45: x | G45: =I42 | J45: = | K45: =IF(C45,C45*E45*G45,"") | L45: Sqm
...
