Workbook

Sheet gen-abstract
A2: NAME OF WORK :- Construction of Hall with Dome Roof at Arthuna [SIZE 16 M X 24 M]
A4: GENERAL ABSTRACT OF COST
B6: PART 'A' CIVIL WORK GROUND FLOOR | F6: Rs. | G6: =GF1_ABS!G28
B8: PART 'B' ELECTRIC WORK @ 12% OF Civil Work | F8: Rs. | G8: =G6*0.12
F10: TOTAL Rs. | G10: =SUM(G6:G8)
B12: Add @ 2 % for Electric Fixtures On Civil Work Part 'A'
C13: i.e. on Rs. | D13: =G6 | F13: Rs. | G13: =ROUNDUP(D13*0.02,0)
E14: GRAND TOTAL Rs. | G14: =SUM(G10:G13)
F16: SAY Rs. | G16: =ROUND(G14/100000,2)
G17: Lacs.
E20: CHARTERED ENGINEER,
E21: RKS TECHNO-LEGAL CONSULTANTS, UDAIPUR

Sheet GF1_ABS
A1: ='gen-abstract'!A2
A3: PART 'A' CIVIL WORK BASEMENT, GROUND FLOOR
A4: ABSTRACT OF COST
A5: S.No. | B5: Particulars. | C5: Quantity | E5: Rate | F5: Unit | G5: Amount
A6: 1 | B6: Earth work in excavation by mechanical means (Hydraulic Excavator )/ manual means in foundation trenches or drains (not exceeding 1.5 m in width or 10 sqm on plan) including dressing of sides and ramming of bottoms, lift upto 1.5 m, including taking out the excavated soil and depositing and refilling of jhiri with watering & ramming and disposal of surplus excavated soil as directed with in a lead of 50 meter. All kinds of soils | C6: =GF1_MES!K22 | D6: Cum | E6: 204.7 | F6: P Cum | G6: =C6*E6
A7: 2 | B7: Filling available excavated earth (excluding rock) in trenches, plinth side of foundation etc. in layers not exceeding 20 cm. in depth , consolidating each deposited layer by ramming and watering including lead upto 50Mtr. and lift upto 1.5Mtr. | C7: =GF1_MES!K34 | D7: Cum | E7: 73.6 | F7: P Cum | G7: =C7*E7
A8: 3 | B8: Providing and laying in position cement concrete including curing compaction etc. of specified grade excluding the cost of centering and shuttering =All up to plinth leve 1:4:8 (1Cement :4 Coarse Sand :8 Graded stone aggregate 40 mm nominal size | C8: =GF1_MES!K38 | D8: Cum | E8: 3797.3 | F8: P Cum | G8: =C8*E8
A9: 4 | B9: Providing and laying in position specified grade of reinforcement cement concrete all RCC structural elements upto plinth level including curing compaction finishing with rendering in cement sand mortar 1:3 ( 1 cement : 3 coarse sand) and making good the joints excluding the cost of centering shuttering and reinforcementlevel. M25 grade Design mix | C9: =GF1_MES!K45 | D9: Cum | E9: =4934+69 | F9: P Cum | G9: =C9*E9
A10: 5 | B10: Centering and shuttering with plywood or steel sheets including strutting, propping, bracing both ways and removal of formwork for foundations in basements rafts, footings, strap beams, bases of columns , etc. up to plinth level. | C10: =GF1_MES!K49 | D10: Sqm | E10: 180.55 | F10: P Sqm | G10: =C10*E10
A11: 6 | B11: Providing and fabricating reinforcement for R.C.C. work including straightening, cutting, bending, placing in position and binding (including cost of binding wire) all complete up to floor three level. Tremo Mechanically treated bars | C11: =GF1_MES!K53 | D11: Kg | E11: 88.55 | F11: P Kg | G11: =C11*E11
A12: 7 | B12: Brick work with F.P.S. bricks of class designation 75 in superstructure above plinth level upto floor V level in all shapes and sizes in : : Cement mortar 1 : 6 (1 cement : 6 coarse sand) | C12: =GF1_MES!K63 | D12: Cum | E12: 5738.5 | F12: P Cum | G12: =C12*E12
A13: 8 | B13: Random Rubble stone masonry for foundation and plinth in Cement Sand mortar above 30 CM thick wall in: Cement Mortar 1:6 ( 1-Cement : 6-Sand). | C13: =GF1_MES!K65 | D13: Cum | E13: 3263.7 | F13: P Cum | G13: =C13*E13
A14: 9 | B14: Plaster on new surface on walls in cement sand mortar 1:6 including raking of joints etc. complete fine finished : 20 mm thick. | C14: =GF1_MES!K83 | D14: Sqm | E14: 218.5 | F14: P Sqm | G14: =IF(C14,ROUNDUP(C14*E14,0),"")
A15: 10 | B15: Providing and fixing T-iron/angle iron frames for doors windows and ventilators of mild steel tee or angle sections joints mitered and welded with 15 x 3 mm lugs, 10 cm. long embedded in cement concrete blocks 15x15x10 cm. size of 1:3:6 (1 cement : 3 coarse sand : 6 graded stone aggregate 20 mm nominal size) or with wooden plugs and screws or rawl plugs and screws or with fixing clips and screws or with bolt and nuts as required including fixing of necessary butt hinges and screws and applying a priming coat of approved steel primer. | C15: =GF1_MES!K88 | D15: Kg | E15: 95.45 | F15: P Kg | G15: =C15*E15
A16: 12.65 | B16: Providing & fixing steel glazed doors, windows and ventilators shutters of standred rolled steel section joint mitred and welded with steel 13x3mm lugs 10 Cm. long embedded in cement concrete blocks 15x10x10 Cm. of 1:3:6 (1-Cement:3-coarse sand:6-graded stone aggregate 20 mm nominal size) or with wooden plugs and screws or rawl plugs and screws or with fixing clips or with bolts and nuts as required, including providing and fixing of plain glass panes 4mm thick with copper glazing clips and special metal-sash putty of approved make, or metal beading with screws complete including priming coat of approved steel primer, excluding the cost of metal beading and other fittings except necessary hinges of pivots steel handles and peg stay etc. as required. Patially fixed and partially openable fixed area not exceed 33% | C16: =GF1_MES!K91 | D16: Sqm | E16: 3553.5 | F16: P Sqm | G16: =C16*E16
A17: 13.8 | B17: Supplying and fixing fixed wire gauge of 14 mesh x 24 gauge to the metal frame of rolled section by metal beading 20x3mm with suitable screw at not exceeding 150 mm distance. | C17: =GF1_MES!K98 | D17: Sqm | E17: 709.55 | G17: =C17*E17
A18: 14.95 | B18: Providing and fixing Square bars or other flat welded to window, ventilators etc. | C18: =GF1_MES!K95 | D18: Kg | E18: 74.75 | G18: =C18*E18
A19: 16.1 | B19: Polished Blue Kota Stone flooring skirting, laid over 20 mm thick base of C.M. 1:4 and jointed with grey cement slurry to match the shade of the slab including rubbing and polishing complete : For area of each slab up to 2001 to 5000 Sq. Cm : (A) 25 mm thick slab. | C19: =GF1_MES!K101 | D19: Sqm | E19: 1176.45 | G19: =C19*E19
A20: 17.25 | B20: Random rubble dry stone Kharanja under floor. | C20: =GF1_MES!K106 | D20: Cum | E20: 1071.8 | F20: P Cum | G20: =C20*E20
A21: 18.4 | B21: White washing with lime to give an even shade including all scaffolding: New work (two or more coats). | C21: =GF1_MES!K113 | D21: Sqm | E21: 12.65 | F21: P Sqm | G21: =IF(C21,ROUNDUP(C21*E21,0),"")
A22: 19.55 | B22: Colour washing of all shades to give an even shade including all scaffolding: New work (two or more coats) with a base coat of white washing with lime. | C22: =GF1_MES!K117 | D22: Sqm | E22: 16.1 | F22: P Sqm | G22: =IF(C22,ROUNDUP(C22*E22,0),"")
A23: 20.7 | B23: Applying priming coat with ready mix pink or Grey primer of approved brand and manufacture on wood work hard and soft wood. | C23: =GF1_MES!K122 | D23: Sqm | E23: 33.35 | F23: P Sqm | G23: =IF(C23,ROUNDUP(C23*E23,0),"")
A24: =A23+1 | B24: Painting with enamel paint of approved brand and manufacture to give an even shade two or more coats on new work. | C24: =GF1_MES!K125 | D24: Sqm | E24: 79.35 | F24: P Sqm | G24: =IF(C24,ROUNDUP(C24*E24,0),"")
A25: 23 | B25: Supply and installation of Multi Rib Proofing/cladding Sheet Manufacture out of 0.50mm TCT (Total Coated Thickness) high tensile Zinc aluminum alloy coated galvalume steel (as per 150gsm zinc aluminum coated 550Mpa tuekd strength) confirming to IS: 1397/astm A-792 sheet to have wide pens 30mm high NB at 250 centre and centre width of 1020mm sheets be casted with regular modified polyster system on a continuous with line on centre for face and with a polyster coating respectively sheet shall have proportionality with siphoned plate made to prevent leakage sheet shall be fixed by more of sell drilling lift tapping hot dip zinc coated hox head fasterner of size 12x14x55mm long. The sheet shall be supplied in cost one length and for a minimum up to 12mts with all scaffolding. | C25: =GF1_MES!K128 | D25: Sqm | E25: 792.35 | F25: P Sqm | G25: =IF(C25,ROUNDUP(C25*E25,0),"")
A26: 24.15 | B26: Add extra for 0.60mm TCT (Total Coated Thickness) high tensile Zinc aluminum alloy coated galvalume steel sheet in place of 0.50mm thick | C26: =C25 | D26: Sqm | E26: 118.85 | F26: P Sqm | G26: =IF(C26,ROUNDUP(C26*E26,0),"")
A27: 25.3 | B27: Structural steel work riveted, bolted or welded in built up sections, trusses and framed work, including cutting, hoisting (height upto 10 m) , fixing in position and applying a priming coat of approved steel primer all complete: | C27: =GF1_MES!K131 | D27: Kg | E27: 93.15 | F27: P Kg | G27: =IF(C27,C27*E27,"")
E28: Total | F28: Rs. | G28: =SUM(G1:G27)
D31: CHARTERED ENGINEER,
D32: RKS TECHNO-LEGAL CONSULTANTS, UDAIPUR

Sheet GF1_MES
A1: ='gen-abstract'!A2
A3: PART 'A' CIVIL WORK FIRST FLOOR
A4: DETAILS OF MEASUREMENTS
A5: S.N. | B5: Particulars | C5: Nos. | E5: Length | G5: Breadth | I5: Height | K5: Qty. | L5: Units
B6: Center to center distances
B7: Ground Floor
B8: Main walls 230 mm th. in x and Y Direction
C9: 2 | D9: x | E9: 16.45 | J9: = | K9: =IF(C9,C9*E9,"") | L9: RM
C10: 2 | D10: x | E10: 13.98 | J10: = | K10: =IF(C9,C9*E9,"") | L10: RM
C11: 2 | D11: x | E11: 16.45 | J11: = | K11: =IF(C9,C9*E9,"") | L11: RM
C12: 2 | D12: x | E12: 18.92 | J12: = | K12: =IF(C9,C9*E9,"") | L12: RM
C13: 2 | D13: x | E13: =E9*1.5 | J13: = | K13: =IF(C10,C10*E10,"") | L13: RM
C14: 2 | D14: x | E14: 11.88 | J14: = | K14: =IF(C9,C9*E9,"") | L14: RM
C15: 2 | D15: x | E15: 13.98 | J15: = | K15: =IF(C9,C9*E9,"") | L15: RM
C16: 2 | D16: x | E16: 16.08 | J16: = | K16: =IF(C9,C9*E9,"") | L16: RM
I17: TOTAL | J17: = | K17: =SUM(K9:K10) | L17: RM
B19: PARAPET WALL 230 MM
B20: Back Side | C20: 1 | D20: x | E20: 0 | J20: = | K20: =IF(C14,C14*E14,"") | L20: RM
C21: 2 | D21: x | E21: 10.1 | J21: = | K21: =IF(C9,C9*E9,"") | L21: RM
C22: 2 | D22: x | E22: 11.88 | J22: = | K22: =IF(C9,C9*E9,"") | L22: RM
C23: 2 | D23: x | E23: 13.66 | J23: = | K23: =IF(C9,C9*E9,"") | L23: RM
I24: TOTAL | J24: = | K24: =SUM(K14:K14) | L24: RM
B25: Brick Partition walls in X and Y Direction
C26: 1 | D26: x | E26: 0 | J26: = | K26: =IF(C17,C17*E17,"") | L26: RM
I27: TOTAL | J27: = | K27: =SUM(K9:K10) | L27: RM
I28: TOTAL | J28: = | K28: =SUM(K9:K10) | L28: RM
I29: TOTAL | J29: = | K29: =SUM(K9:K10) | L29: RM
I30: TOTAL | J30: = | K30: =SUM(K17:K17) | L30: RM
A32: 1 | B32: Earth work in excavation in foundation trenches or drains including dressing of sides and ramming of bottoms, lift up to 1.5 Mtr. including taking out the excavated soil and depositing and refilling of jhiri with watering & ramming and disposal of surplus excavated soil as directed within a lead of 50 meter. All kinds of soil.
C33: 1 | D33: x | E33: =E9 | F33: x | G33: =E10 | H33: x | I33: 1.2 | J33: = | K33: =IF(C21,C21*E21*G21*I21,"") | L33: Cum
C34: 2 | D34: x | E34: 8.58 | J34: = | K34: =IF(C9,C9*E9,"") | L34: RM
C35: 2 | D35: x | E35: 10.1 | J35: = | K35: =IF(C9,C9*E9,"") | L35: RM
C36: 2 | D36: x | E36: 11.61 | J36: = | K36: =IF(C9,C9*E9,"") | L36: RM
G37: Total | K37: =SUM(K21:K21) | L37: Cum
A38: 2 | B38: Filling available excavated earth (excluding rock) in trenches, plinth side of foundation etc. in layers not exceeding 20 cm. in depth , consolidating each deposited layer by ramming and watering including lead upto 50Mtr. and lift upto 1.5Mtr. | I38: =E24*G24
B39: Average Width (49.83+18.44)/2=34.14
B40: Area of Open Excavation | C40: 1 | D40: x | E40: =E21 | F40: x | G40: =G21 | J40: = | K40: =IF(C25,C25*E25*G25,"") | L40: Sqm
B41: Deductions
B42: Footing Area
B43: C1 | C43: =ROUNDUP(E10/4,0)*2 | D43: x | E43: 2 | F43: x | G43: 2.3 | J43: = | K43: =IF(C28,C28*E28*G28,"") | L43: Sqm
...
